[2023-01-05 13:13:31,111] [autoreload.py:677] [autoreload:run_with_reloader] [INFO]- Watching for file changes with StatReloader
[2023-01-05 13:13:56,456] [server.py:111] [server:run] [INFO]- HTTP/2 support enabled
[2023-01-05 13:13:56,456] [server.py:122] [server:run] [INFO]- Configuring endpoint tcp:port=8000:interface=127.0.0.1
[2023-01-05 13:13:56,458] [server.py:153] [server:listen_success] [INFO]- Listening on TCP address 127.0.0.1:8000
[2023-01-05 13:15:58,893] [runserver.py:147] [runserver:log_action] [INFO]- HTTP GET /projects/ 200 [1.94, 127.0.0.1:50376]
[2023-01-05 13:15:59,671] [runserver.py:147] [runserver:log_action] [INFO]- HTTP GET /cases/ 200 [2.61, 127.0.0.1:50377]
[2023-01-05 13:16:11,566] [fiddlerExe.py:37] [fiddlerExe:getDatas] [INFO]- True
[2023-01-05 13:16:11,577] [runserver.py:147] [runserver:log_action] [INFO]- HTTP POST /dealFiddler/ 200 [0.13, 127.0.0.1:50387]
[2023-01-05 13:30:13,619] [runserver.py:147] [runserver:log_action] [INFO]- HTTP GET /cases/ 200 [0.50, 127.0.0.1:50875]
[2023-01-05 13:32:45,105] [autoreload.py:266] [autoreload:trigger_reload] [INFO]- C:\Users\Administrator\Desktop\myweb\myweb\saas\fiddlerExe.py changed, reloading.
[2023-01-05 13:33:16,573] [autoreload.py:677] [autoreload:run_with_reloader] [INFO]- Watching for file changes with StatReloader
[2023-01-05 13:33:19,896] [server.py:111] [server:run] [INFO]- HTTP/2 support enabled
[2023-01-05 13:33:19,896] [server.py:122] [server:run] [INFO]- Configuring endpoint tcp:port=8000:interface=127.0.0.1
[2023-01-05 13:33:19,896] [server.py:153] [server:listen_success] [INFO]- Listening on TCP address 127.0.0.1:8000
[2023-01-05 13:33:33,064] [fiddlerExe.py:37] [fiddlerExe:getDatas] [INFO]- True
[2023-01-05 13:33:33,072] [runserver.py:147] [runserver:log_action] [INFO]- HTTP POST /dealFiddler/ 200 [0.13, 127.0.0.1:50976]
[2023-01-05 13:33:45,076] [runserver.py:147] [runserver:log_action] [INFO]- HTTP POST /cases/ 200 [1.61, 127.0.0.1:50984]
[2023-01-05 13:33:45,076] [runserver.py:147] [runserver:log_action] [INFO]- HTTP POST /cases/ 200 [1.60, 127.0.0.1:50987]
[2023-01-05 13:33:52,695] [runserver.py:147] [runserver:log_action] [INFO]- HTTP GET /cases/ 200 [0.16, 127.0.0.1:50999]
[2023-01-05 13:34:12,317] [runserver.py:147] [runserver:log_action] [INFO]- HTTP GET /cases/ 200 [0.25, 127.0.0.1:51016]
[2023-01-05 13:34:12,345] [runserver.py:147] [runserver:log_action] [INFO]- HTTP GET /projects/ 200 [0.26, 127.0.0.1:51017]
[2023-01-05 13:34:12,934] [runserver.py:147] [runserver:log_action] [INFO]- HTTP GET /cases/48 200 [0.23, 127.0.0.1:51023]
[2023-01-05 13:34:14,830] [runserver.py:147] [runserver:log_action] [INFO]- HTTP GET /modules/?project= 200 [0.47, 127.0.0.1:51027]
[2023-01-05 13:34:22,747] [runserver.py:147] [runserver:log_action] [INFO]- HTTP GET /cases/ 200 [0.11, 127.0.0.1:51034]
[2023-01-05 13:34:26,594] [runserver.py:147] [runserver:log_action] [INFO]- HTTP GET /cases/ 200 [0.11, 127.0.0.1:51045]
[2023-01-05 13:34:26,626] [runserver.py:147] [runserver:log_action] [INFO]- HTTP GET /projects/ 200 [0.14, 127.0.0.1:51044]
[2023-01-05 13:34:26,798] [runserver.py:147] [runserver:log_action] [INFO]- HTTP GET /cases/54 200 [0.06, 127.0.0.1:51051]
[2023-01-05 13:34:27,075] [runserver.py:147] [runserver:log_action] [INFO]- HTTP GET /modules/?project= 200 [0.04, 127.0.0.1:51055]
[2023-01-05 13:34:34,961] [runserver.py:147] [runserver:log_action] [INFO]- HTTP GET /cases/ 200 [0.08, 127.0.0.1:51066]
[2023-01-05 13:34:40,699] [runserver.py:147] [runserver:log_action] [INFO]- HTTP GET /projects/ 200 [0.06, 127.0.0.1:51076]
[2023-01-05 13:34:40,746] [runserver.py:147] [runserver:log_action] [INFO]- HTTP GET /cases/ 200 [0.11, 127.0.0.1:51077]
[2023-01-05 13:34:40,885] [runserver.py:147] [runserver:log_action] [INFO]- HTTP GET /cases/54 200 [0.03, 127.0.0.1:51083]
[2023-01-05 13:34:41,142] [runserver.py:147] [runserver:log_action] [INFO]- HTTP GET /modules/?project= 200 [0.05, 127.0.0.1:51087]
[2023-01-05 13:34:43,083] [runserver.py:147] [runserver:log_action] [INFO]- HTTP GET /cases/ 200 [0.09, 127.0.0.1:51089]
[2023-01-05 13:34:47,916] [runserver.py:147] [runserver:log_action] [INFO]- HTTP GET /projects/ 200 [0.11, 127.0.0.1:51100]
[2023-01-05 13:34:47,916] [runserver.py:147] [runserver:log_action] [INFO]- HTTP GET /cases/ 200 [0.11, 127.0.0.1:51101]
[2023-01-05 13:34:48,088] [runserver.py:147] [runserver:log_action] [INFO]- HTTP GET /cases/55 200 [0.03, 127.0.0.1:51107]
[2023-01-05 13:34:48,383] [runserver.py:147] [runserver:log_action] [INFO]- HTTP GET /modules/?project= 200 [0.07, 127.0.0.1:51111]
[2023-01-05 13:36:05,730] [fiddlerExe.py:37] [fiddlerExe:getDatas] [INFO]- True
[2023-01-05 13:36:05,739] [runserver.py:147] [runserver:log_action] [INFO]- HTTP POST /dealFiddler/ 200 [0.02, 127.0.0.1:51175]
[2023-01-05 13:37:16,944] [runserver.py:147] [runserver:log_action] [INFO]- HTTP GET /deleteAuto/ 200 [0.08, 127.0.0.1:51225]
[2023-01-05 13:40:15,631] [log.py:241] [log:log_response] [ERROR]- Internal Server Error: /dealFiddler/
Traceback (most recent call last):
  File "D:\pythonList\web_python310\lib\site-packages\asgiref\sync.py", line 472, in thread_handler
    raise exc_info[1]
  File "D:\pythonList\web_python310\lib\site-packages\django\core\handlers\exception.py", line 42, in inner
    response = await get_response(request)
  File "D:\pythonList\web_python310\lib\site-packages\django\core\handlers\base.py", line 253, in _get_response_async
    response = await wrapped_callback(
  File "D:\pythonList\web_python310\lib\site-packages\asgiref\sync.py", line 435, in __call__
    ret = await asyncio.wait_for(future, timeout=None)
  File "D:\Python310\lib\asyncio\tasks.py", line 408, in wait_for
    return await fut
  File "D:\Python310\lib\concurrent\futures\thread.py", line 52, in run
    result = self.fn(*self.args, **self.kwargs)
  File "D:\pythonList\web_python310\lib\site-packages\asgiref\sync.py", line 476, in thread_handler
    return func(*args, **kwargs)
  File "D:\pythonList\web_python310\lib\site-packages\django\views\decorators\csrf.py", line 54, in wrapped_view
    return view_func(*args, **kwargs)
  File "D:\pythonList\web_python310\lib\site-packages\django\views\generic\base.py", line 103, in view
    return self.dispatch(request, *args, **kwargs)
  File "D:\pythonList\web_python310\lib\site-packages\rest_framework\views.py", line 509, in dispatch
    response = self.handle_exception(exc)
  File "D:\pythonList\web_python310\lib\site-packages\rest_framework\views.py", line 469, in handle_exception
    self.raise_uncaught_exception(exc)
  File "D:\pythonList\web_python310\lib\site-packages\rest_framework\views.py", line 480, in raise_uncaught_exception
    raise exc
  File "D:\pythonList\web_python310\lib\site-packages\rest_framework\views.py", line 506, in dispatch
    response = handler(request, *args, **kwargs)
  File "C:\Users\Administrator\Desktop\myweb\myweb\saas\views.py", line 676, in post
    datas = fiddlerExe.getDatas(data['hosts'])
  File "C:\Users\Administrator\Desktop\myweb\myweb\saas\fiddlerExe.py", line 30, in getDatas
    with open(r'D:\auto.dat', 'rb') as f1:
FileNotFoundError: [Errno 2] No such file or directory: 'D:\\auto.dat'
[2023-01-05 13:40:15,642] [runserver.py:160] [runserver:log_action] [ERROR]- HTTP POST /dealFiddler/ 500 [0.55, 127.0.0.1:51746]
[2023-01-05 13:40:48,887] [fiddlerExe.py:37] [fiddlerExe:getDatas] [INFO]- True
[2023-01-05 13:40:48,907] [runserver.py:147] [runserver:log_action] [INFO]- HTTP POST /dealFiddler/ 200 [0.08, 127.0.0.1:51797]
[2023-01-05 13:44:19,244] [autoreload.py:266] [autoreload:trigger_reload] [INFO]- C:\Users\Administrator\Desktop\myweb\myweb\saas\fiddlerExe.py changed, reloading.
[2023-01-05 13:44:40,970] [autoreload.py:677] [autoreload:run_with_reloader] [INFO]- Watching for file changes with StatReloader
[2023-01-05 13:44:44,121] [server.py:111] [server:run] [INFO]- HTTP/2 support enabled
[2023-01-05 13:44:44,121] [server.py:122] [server:run] [INFO]- Configuring endpoint tcp:port=8000:interface=127.0.0.1
[2023-01-05 13:44:44,137] [server.py:153] [server:listen_success] [INFO]- Listening on TCP address 127.0.0.1:8000
[2023-01-05 13:47:24,709] [autoreload.py:266] [autoreload:trigger_reload] [INFO]- C:\Users\Administrator\Desktop\myweb\myweb\saas\fiddlerExe.py changed, reloading.
[2023-01-05 13:47:30,995] [autoreload.py:677] [autoreload:run_with_reloader] [INFO]- Watching for file changes with StatReloader
[2023-01-05 13:47:31,432] [server.py:111] [server:run] [INFO]- HTTP/2 support enabled
[2023-01-05 13:47:31,432] [server.py:122] [server:run] [INFO]- Configuring endpoint tcp:port=8000:interface=127.0.0.1
[2023-01-05 13:47:31,432] [server.py:153] [server:listen_success] [INFO]- Listening on TCP address 127.0.0.1:8000
[2023-01-05 14:41:47,721] [autoreload.py:266] [autoreload:trigger_reload] [INFO]- C:\Users\Administrator\Desktop\myweb\myweb\saas\fiddlerExe.py changed, reloading.
[2023-01-05 14:42:11,931] [autoreload.py:677] [autoreload:run_with_reloader] [INFO]- Watching for file changes with StatReloader
[2023-01-05 14:43:01,674] [autoreload.py:266] [autoreload:trigger_reload] [INFO]- C:\Users\Administrator\Desktop\myweb\myweb\saas\fiddlerExe.py changed, reloading.
[2023-01-05 14:43:04,825] [autoreload.py:677] [autoreload:run_with_reloader] [INFO]- Watching for file changes with StatReloader
[2023-01-05 14:45:37,183] [autoreload.py:677] [autoreload:run_with_reloader] [INFO]- Watching for file changes with StatReloader
[2023-01-05 14:45:41,161] [server.py:111] [server:run] [INFO]- HTTP/2 support enabled
[2023-01-05 14:45:41,161] [server.py:122] [server:run] [INFO]- Configuring endpoint tcp:port=8000:interface=127.0.0.1
[2023-01-05 14:45:41,176] [server.py:153] [server:listen_success] [INFO]- Listening on TCP address 127.0.0.1:8000
[2023-01-05 14:45:55,213] [fiddlerExe.py:37] [fiddlerExe:getDatas] [INFO]- True
[2023-01-05 14:45:55,283] [runserver.py:147] [runserver:log_action] [INFO]- HTTP POST /dealFiddler/ 200 [0.34, 127.0.0.1:53646]
[2023-01-05 14:46:04,443] [runserver.py:147] [runserver:log_action] [INFO]- HTTP GET /cases/ 200 [1.21, 127.0.0.1:53654]
[2023-01-05 14:46:25,117] [fiddlerExe.py:37] [fiddlerExe:getDatas] [INFO]- True
[2023-01-05 14:46:25,127] [runserver.py:147] [runserver:log_action] [INFO]- HTTP POST /dealFiddler/ 200 [0.30, 127.0.0.1:53682]
[2023-01-05 14:47:10,018] [autoreload.py:266] [autoreload:trigger_reload] [INFO]- C:\Users\Administrator\Desktop\myweb\myweb\saas\fiddlerExe.py changed, reloading.
[2023-01-05 14:47:24,948] [autoreload.py:677] [autoreload:run_with_reloader] [INFO]- Watching for file changes with StatReloader
[2023-01-05 14:47:27,891] [server.py:111] [server:run] [INFO]- HTTP/2 support enabled
[2023-01-05 14:47:27,891] [server.py:122] [server:run] [INFO]- Configuring endpoint tcp:port=8000:interface=127.0.0.1
[2023-01-05 14:47:27,893] [server.py:153] [server:listen_success] [INFO]- Listening on TCP address 127.0.0.1:8000
[2023-01-05 14:47:39,882] [fiddlerExe.py:37] [fiddlerExe:getDatas] [INFO]- True
[2023-01-05 14:47:39,897] [runserver.py:147] [runserver:log_action] [INFO]- HTTP POST /dealFiddler/ 200 [0.80, 127.0.0.1:53878]
[2023-01-05 14:48:45,789] [runserver.py:147] [runserver:log_action] [INFO]- HTTP POST /cases/ 200 [2.55, 127.0.0.1:53938]
[2023-01-05 14:48:45,956] [runserver.py:147] [runserver:log_action] [INFO]- HTTP POST /cases/ 200 [2.72, 127.0.0.1:53940]
[2023-01-05 14:48:45,968] [runserver.py:147] [runserver:log_action] [INFO]- HTTP POST /cases/ 200 [2.73, 127.0.0.1:53939]
[2023-01-05 14:48:45,972] [runserver.py:147] [runserver:log_action] [INFO]- HTTP POST /cases/ 200 [2.76, 127.0.0.1:53937]
[2023-01-05 14:48:46,075] [runserver.py:147] [runserver:log_action] [INFO]- HTTP POST /cases/ 200 [2.84, 127.0.0.1:53942]
[2023-01-05 14:48:46,088] [runserver.py:147] [runserver:log_action] [INFO]- HTTP POST /cases/ 200 [2.85, 127.0.0.1:53941]
[2023-01-05 14:48:46,706] [runserver.py:147] [runserver:log_action] [INFO]- HTTP POST /cases/ 200 [0.78, 127.0.0.1:53953]
[2023-01-05 14:48:53,243] [runserver.py:147] [runserver:log_action] [INFO]- HTTP POST /cases/ 200 [5.12, 127.0.0.1:53972]
[2023-01-05 14:48:53,432] [runserver.py:147] [runserver:log_action] [INFO]- HTTP POST /cases/ 200 [7.22, 127.0.0.1:53959]
[2023-01-05 14:48:53,472] [runserver.py:147] [runserver:log_action] [INFO]- HTTP POST /cases/ 200 [5.14, 127.0.0.1:53976]
[2023-01-05 14:48:53,692] [runserver.py:147] [runserver:log_action] [INFO]- HTTP POST /cases/ 200 [5.48, 127.0.0.1:53973]
[2023-01-05 14:48:55,814] [log.py:241] [log:log_response] [ERROR]- Internal Server Error: /cases/
Traceback (most recent call last):
  File "D:\pythonList\web_python310\lib\site-packages\django\db\backends\utils.py", line 89, in _execute
    return self.cursor.execute(sql, params)
  File "D:\pythonList\web_python310\lib\site-packages\django\db\backends\mysql\base.py", line 75, in execute
    return self.cursor.execute(query, args)
  File "D:\pythonList\web_python310\lib\site-packages\pymysql\cursors.py", line 148, in execute
    result = self._query(query)
  File "D:\pythonList\web_python310\lib\site-packages\pymysql\cursors.py", line 310, in _query
    conn.query(q)
  File "D:\pythonList\web_python310\lib\site-packages\pymysql\connections.py", line 548, in query
    self._affected_rows = self._read_query_result(unbuffered=unbuffered)
  File "D:\pythonList\web_python310\lib\site-packages\pymysql\connections.py", line 775, in _read_query_result
    result.read()
  File "D:\pythonList\web_python310\lib\site-packages\pymysql\connections.py", line 1156, in read
    first_packet = self.connection._read_packet()
  File "D:\pythonList\web_python310\lib\site-packages\pymysql\connections.py", line 725, in _read_packet
    packet.raise_for_error()
  File "D:\pythonList\web_python310\lib\site-packages\pymysql\protocol.py", line 221, in raise_for_error
    err.raise_mysql_exception(self._data)
  File "D:\pythonList\web_python310\lib\site-packages\pymysql\err.py", line 143, in raise_mysql_exception
    raise errorclass(errno, errval)
pymysql.err.DataError: (1366, "Incorrect string value: '\\xF0\\x9F\\x91\\x8D\\xE9\\x9A...' for column 'unchange' at row 1")

The above exception was the direct cause of the following exception:

Traceback (most recent call last):
  File "D:\pythonList\web_python310\lib\site-packages\asgiref\sync.py", line 472, in thread_handler
    raise exc_info[1]
  File "D:\pythonList\web_python310\lib\site-packages\django\core\handlers\exception.py", line 42, in inner
    response = await get_response(request)
  File "D:\pythonList\web_python310\lib\site-packages\django\core\handlers\base.py", line 253, in _get_response_async
    response = await wrapped_callback(
  File "D:\pythonList\web_python310\lib\site-packages\asgiref\sync.py", line 435, in __call__
    ret = await asyncio.wait_for(future, timeout=None)
  File "D:\Python310\lib\asyncio\tasks.py", line 408, in wait_for
    return await fut
  File "D:\Python310\lib\concurrent\futures\thread.py", line 52, in run
    result = self.fn(*self.args, **self.kwargs)
  File "D:\pythonList\web_python310\lib\site-packages\asgiref\sync.py", line 476, in thread_handler
    return func(*args, **kwargs)
  File "D:\pythonList\web_python310\lib\site-packages\django\views\decorators\csrf.py", line 54, in wrapped_view
    return view_func(*args, **kwargs)
  File "D:\pythonList\web_python310\lib\site-packages\django\views\generic\base.py", line 103, in view
    return self.dispatch(request, *args, **kwargs)
  File "D:\pythonList\web_python310\lib\site-packages\rest_framework\views.py", line 509, in dispatch
    response = self.handle_exception(exc)
  File "D:\pythonList\web_python310\lib\site-packages\rest_framework\views.py", line 469, in handle_exception
    self.raise_uncaught_exception(exc)
  File "D:\pythonList\web_python310\lib\site-packages\rest_framework\views.py", line 480, in raise_uncaught_exception
    raise exc
  File "D:\pythonList\web_python310\lib\site-packages\rest_framework\views.py", line 506, in dispatch
    response = handler(request, *args, **kwargs)
  File "C:\Users\Administrator\Desktop\myweb\myweb\saas\views.py", line 438, in post
    serialize.save()
  File "D:\pythonList\web_python310\lib\site-packages\rest_framework\serializers.py", line 212, in save
    self.instance = self.create(validated_data)
  File "D:\pythonList\web_python310\lib\site-packages\rest_framework\serializers.py", line 962, in create
    instance = ModelClass._default_manager.create(**validated_data)
  File "D:\pythonList\web_python310\lib\site-packages\django\db\models\manager.py", line 85, in manager_method
    return getattr(self.get_queryset(), name)(*args, **kwargs)
  File "D:\pythonList\web_python310\lib\site-packages\django\db\models\query.py", line 671, in create
    obj.save(force_insert=True, using=self.db)
  File "D:\pythonList\web_python310\lib\site-packages\django\db\models\base.py", line 812, in save
    self.save_base(
  File "D:\pythonList\web_python310\lib\site-packages\django\db\models\base.py", line 863, in save_base
    updated = self._save_table(
  File "D:\pythonList\web_python310\lib\site-packages\django\db\models\base.py", line 1006, in _save_table
    results = self._do_insert(
  File "D:\pythonList\web_python310\lib\site-packages\django\db\models\base.py", line 1047, in _do_insert
    return manager._insert(
  File "D:\pythonList\web_python310\lib\site-packages\django\db\models\manager.py", line 85, in manager_method
    return getattr(self.get_queryset(), name)(*args, **kwargs)
  File "D:\pythonList\web_python310\lib\site-packages\django\db\models\query.py", line 1791, in _insert
    return query.get_compiler(using=using).execute_sql(returning_fields)
  File "D:\pythonList\web_python310\lib\site-packages\django\db\models\sql\compiler.py", line 1660, in execute_sql
    cursor.execute(sql, params)
  File "D:\pythonList\web_python310\lib\site-packages\django\db\backends\utils.py", line 103, in execute
    return super().execute(sql, params)
  File "D:\pythonList\web_python310\lib\site-packages\django\db\backends\utils.py", line 67, in execute
    return self._execute_with_wrappers(
  File "D:\pythonList\web_python310\lib\site-packages\django\db\backends\utils.py", line 80, in _execute_with_wrappers
    return executor(sql, params, many, context)
  File "D:\pythonList\web_python310\lib\site-packages\django\db\backends\utils.py", line 84, in _execute
    with self.db.wrap_database_errors:
  File "D:\pythonList\web_python310\lib\site-packages\django\db\utils.py", line 91, in __exit__
    raise dj_exc_value.with_traceback(traceback) from exc_value
  File "D:\pythonList\web_python310\lib\site-packages\django\db\backends\utils.py", line 89, in _execute
    return self.cursor.execute(sql, params)
  File "D:\pythonList\web_python310\lib\site-packages\django\db\backends\mysql\base.py", line 75, in execute
    return self.cursor.execute(query, args)
  File "D:\pythonList\web_python310\lib\site-packages\pymysql\cursors.py", line 148, in execute
    result = self._query(query)
  File "D:\pythonList\web_python310\lib\site-packages\pymysql\cursors.py", line 310, in _query
    conn.query(q)
  File "D:\pythonList\web_python310\lib\site-packages\pymysql\connections.py", line 548, in query
    self._affected_rows = self._read_query_result(unbuffered=unbuffered)
  File "D:\pythonList\web_python310\lib\site-packages\pymysql\connections.py", line 775, in _read_query_result
    result.read()
  File "D:\pythonList\web_python310\lib\site-packages\pymysql\connections.py", line 1156, in read
    first_packet = self.connection._read_packet()
  File "D:\pythonList\web_python310\lib\site-packages\pymysql\connections.py", line 725, in _read_packet
    packet.raise_for_error()
  File "D:\pythonList\web_python310\lib\site-packages\pymysql\protocol.py", line 221, in raise_for_error
    err.raise_mysql_exception(self._data)
  File "D:\pythonList\web_python310\lib\site-packages\pymysql\err.py", line 143, in raise_mysql_exception
    raise errorclass(errno, errval)
django.db.utils.DataError: (1366, "Incorrect string value: '\\xF0\\x9F\\x91\\x8D\\xE9\\x9A...' for column 'unchange' at row 1")
[2023-01-05 14:48:55,838] [log.py:241] [log:log_response] [ERROR]- Internal Server Error: /cases/
Traceback (most recent call last):
  File "D:\pythonList\web_python310\lib\site-packages\django\db\backends\utils.py", line 89, in _execute
    return self.cursor.execute(sql, params)
  File "D:\pythonList\web_python310\lib\site-packages\django\db\backends\mysql\base.py", line 75, in execute
    return self.cursor.execute(query, args)
  File "D:\pythonList\web_python310\lib\site-packages\pymysql\cursors.py", line 148, in execute
    result = self._query(query)
  File "D:\pythonList\web_python310\lib\site-packages\pymysql\cursors.py", line 310, in _query
    conn.query(q)
  File "D:\pythonList\web_python310\lib\site-packages\pymysql\connections.py", line 548, in query
    self._affected_rows = self._read_query_result(unbuffered=unbuffered)
  File "D:\pythonList\web_python310\lib\site-packages\pymysql\connections.py", line 775, in _read_query_result
    result.read()
  File "D:\pythonList\web_python310\lib\site-packages\pymysql\connections.py", line 1156, in read
    first_packet = self.connection._read_packet()
  File "D:\pythonList\web_python310\lib\site-packages\pymysql\connections.py", line 725, in _read_packet
    packet.raise_for_error()
  File "D:\pythonList\web_python310\lib\site-packages\pymysql\protocol.py", line 221, in raise_for_error
    err.raise_mysql_exception(self._data)
  File "D:\pythonList\web_python310\lib\site-packages\pymysql\err.py", line 143, in raise_mysql_exception
    raise errorclass(errno, errval)
pymysql.err.DataError: (1366, 'Incorrect string value: \'\\xF0\\x9F\\x98\\x84",...\' for column \'unchange\' at row 1')

The above exception was the direct cause of the following exception:

Traceback (most recent call last):
  File "D:\pythonList\web_python310\lib\site-packages\asgiref\sync.py", line 472, in thread_handler
    raise exc_info[1]
  File "D:\pythonList\web_python310\lib\site-packages\django\core\handlers\exception.py", line 42, in inner
    response = await get_response(request)
  File "D:\pythonList\web_python310\lib\site-packages\django\core\handlers\base.py", line 253, in _get_response_async
    response = await wrapped_callback(
  File "D:\pythonList\web_python310\lib\site-packages\asgiref\sync.py", line 435, in __call__
    ret = await asyncio.wait_for(future, timeout=None)
  File "D:\Python310\lib\asyncio\tasks.py", line 408, in wait_for
    return await fut
  File "D:\Python310\lib\concurrent\futures\thread.py", line 52, in run
    result = self.fn(*self.args, **self.kwargs)
  File "D:\pythonList\web_python310\lib\site-packages\asgiref\sync.py", line 476, in thread_handler
    return func(*args, **kwargs)
  File "D:\pythonList\web_python310\lib\site-packages\django\views\decorators\csrf.py", line 54, in wrapped_view
    return view_func(*args, **kwargs)
  File "D:\pythonList\web_python310\lib\site-packages\django\views\generic\base.py", line 103, in view
    return self.dispatch(request, *args, **kwargs)
  File "D:\pythonList\web_python310\lib\site-packages\rest_framework\views.py", line 509, in dispatch
    response = self.handle_exception(exc)
  File "D:\pythonList\web_python310\lib\site-packages\rest_framework\views.py", line 469, in handle_exception
    self.raise_uncaught_exception(exc)
  File "D:\pythonList\web_python310\lib\site-packages\rest_framework\views.py", line 480, in raise_uncaught_exception
    raise exc
  File "D:\pythonList\web_python310\lib\site-packages\rest_framework\views.py", line 506, in dispatch
    response = handler(request, *args, **kwargs)
  File "C:\Users\Administrator\Desktop\myweb\myweb\saas\views.py", line 438, in post
    serialize.save()
  File "D:\pythonList\web_python310\lib\site-packages\rest_framework\serializers.py", line 212, in save
    self.instance = self.create(validated_data)
  File "D:\pythonList\web_python310\lib\site-packages\rest_framework\serializers.py", line 962, in create
    instance = ModelClass._default_manager.create(**validated_data)
  File "D:\pythonList\web_python310\lib\site-packages\django\db\models\manager.py", line 85, in manager_method
    return getattr(self.get_queryset(), name)(*args, **kwargs)
  File "D:\pythonList\web_python310\lib\site-packages\django\db\models\query.py", line 671, in create
    obj.save(force_insert=True, using=self.db)
  File "D:\pythonList\web_python310\lib\site-packages\django\db\models\base.py", line 812, in save
    self.save_base(
  File "D:\pythonList\web_python310\lib\site-packages\django\db\models\base.py", line 863, in save_base
    updated = self._save_table(
  File "D:\pythonList\web_python310\lib\site-packages\django\db\models\base.py", line 1006, in _save_table
    results = self._do_insert(
  File "D:\pythonList\web_python310\lib\site-packages\django\db\models\base.py", line 1047, in _do_insert
    return manager._insert(
  File "D:\pythonList\web_python310\lib\site-packages\django\db\models\manager.py", line 85, in manager_method
    return getattr(self.get_queryset(), name)(*args, **kwargs)
  File "D:\pythonList\web_python310\lib\site-packages\django\db\models\query.py", line 1791, in _insert
    return query.get_compiler(using=using).execute_sql(returning_fields)
  File "D:\pythonList\web_python310\lib\site-packages\django\db\models\sql\compiler.py", line 1660, in execute_sql
    cursor.execute(sql, params)
  File "D:\pythonList\web_python310\lib\site-packages\django\db\backends\utils.py", line 103, in execute
    return super().execute(sql, params)
  File "D:\pythonList\web_python310\lib\site-packages\django\db\backends\utils.py", line 67, in execute
    return self._execute_with_wrappers(
  File "D:\pythonList\web_python310\lib\site-packages\django\db\backends\utils.py", line 80, in _execute_with_wrappers
    return executor(sql, params, many, context)
  File "D:\pythonList\web_python310\lib\site-packages\django\db\backends\utils.py", line 84, in _execute
    with self.db.wrap_database_errors:
  File "D:\pythonList\web_python310\lib\site-packages\django\db\utils.py", line 91, in __exit__
    raise dj_exc_value.with_traceback(traceback) from exc_value
  File "D:\pythonList\web_python310\lib\site-packages\django\db\backends\utils.py", line 89, in _execute
    return self.cursor.execute(sql, params)
  File "D:\pythonList\web_python310\lib\site-packages\django\db\backends\mysql\base.py", line 75, in execute
    return self.cursor.execute(query, args)
  File "D:\pythonList\web_python310\lib\site-packages\pymysql\cursors.py", line 148, in execute
    result = self._query(query)
  File "D:\pythonList\web_python310\lib\site-packages\pymysql\cursors.py", line 310, in _query
    conn.query(q)
  File "D:\pythonList\web_python310\lib\site-packages\pymysql\connections.py", line 548, in query
    self._affected_rows = self._read_query_result(unbuffered=unbuffered)
  File "D:\pythonList\web_python310\lib\site-packages\pymysql\connections.py", line 775, in _read_query_result
    result.read()
  File "D:\pythonList\web_python310\lib\site-packages\pymysql\connections.py", line 1156, in read
    first_packet = self.connection._read_packet()
  File "D:\pythonList\web_python310\lib\site-packages\pymysql\connections.py", line 725, in _read_packet
    packet.raise_for_error()
  File "D:\pythonList\web_python310\lib\site-packages\pymysql\protocol.py", line 221, in raise_for_error
    err.raise_mysql_exception(self._data)
  File "D:\pythonList\web_python310\lib\site-packages\pymysql\err.py", line 143, in raise_mysql_exception
    raise errorclass(errno, errval)
django.db.utils.DataError: (1366, 'Incorrect string value: \'\\xF0\\x9F\\x98\\x84",...\' for column \'unchange\' at row 1')
[2023-01-05 14:48:55,869] [runserver.py:160] [runserver:log_action] [ERROR]- HTTP POST /cases/ 500 [7.79, 127.0.0.1:53971]
[2023-01-05 14:48:55,876] [runserver.py:160] [runserver:log_action] [ERROR]- HTTP POST /cases/ 500 [8.82, 127.0.0.1:53962]
[2023-01-05 14:49:10,104] [runserver.py:147] [runserver:log_action] [INFO]- HTTP GET /cases/ 200 [0.32, 127.0.0.1:53996]
[2023-01-05 14:49:31,328] [runserver.py:147] [runserver:log_action] [INFO]- HTTP GET /cases/?page=2 200 [0.06, 127.0.0.1:54024]
[2023-01-05 14:49:45,370] [runserver.py:147] [runserver:log_action] [INFO]- HTTP GET /cases/?page=1 200 [0.10, 127.0.0.1:54037]
[2023-01-05 14:49:59,502] [runserver.py:147] [runserver:log_action] [INFO]- HTTP GET /cases/?page=2 200 [0.09, 127.0.0.1:54047]
[2023-01-05 15:22:11,921] [runserver.py:147] [runserver:log_action] [INFO]- HTTP GET /cases/?search=shakespeare%2Fnotes%2F108710063%2Fuser_notes 200 [0.33, 127.0.0.1:54255]
[2023-01-05 15:22:22,705] [runserver.py:147] [runserver:log_action] [INFO]- HTTP GET /cases/?search= 200 [0.10, 127.0.0.1:54259]
[2023-01-05 15:22:26,785] [runserver.py:147] [runserver:log_action] [INFO]- HTTP GET /cases/?page=2 200 [0.07, 127.0.0.1:54265]
[2023-01-05 15:23:03,679] [runserver.py:147] [runserver:log_action] [INFO]- HTTP GET /cases/?page=1 200 [0.06, 127.0.0.1:54274]
[2023-01-05 15:23:25,137] [runserver.py:147] [runserver:log_action] [INFO]- HTTP GET /cases/?search=shakespeare%2Fnotes%2F6d5a7dae205d%2Ffeatured_comments 200 [0.15, 127.0.0.1:54281]
[2023-01-05 15:23:30,189] [runserver.py:147] [runserver:log_action] [INFO]- HTTP GET /cases/?search= 200 [0.13, 127.0.0.1:54287]
[2023-01-05 15:23:43,416] [log.py:241] [log:log_response] [ERROR]- Internal Server Error: /cases/
Traceback (most recent call last):
  File "D:\pythonList\web_python310\lib\site-packages\django\db\backends\utils.py", line 89, in _execute
    return self.cursor.execute(sql, params)
  File "D:\pythonList\web_python310\lib\site-packages\django\db\backends\mysql\base.py", line 75, in execute
    return self.cursor.execute(query, args)
  File "D:\pythonList\web_python310\lib\site-packages\pymysql\cursors.py", line 148, in execute
    result = self._query(query)
  File "D:\pythonList\web_python310\lib\site-packages\pymysql\cursors.py", line 310, in _query
    conn.query(q)
  File "D:\pythonList\web_python310\lib\site-packages\pymysql\connections.py", line 548, in query
    self._affected_rows = self._read_query_result(unbuffered=unbuffered)
  File "D:\pythonList\web_python310\lib\site-packages\pymysql\connections.py", line 775, in _read_query_result
    result.read()
  File "D:\pythonList\web_python310\lib\site-packages\pymysql\connections.py", line 1156, in read
    first_packet = self.connection._read_packet()
  File "D:\pythonList\web_python310\lib\site-packages\pymysql\connections.py", line 725, in _read_packet
    packet.raise_for_error()
  File "D:\pythonList\web_python310\lib\site-packages\pymysql\protocol.py", line 221, in raise_for_error
    err.raise_mysql_exception(self._data)
  File "D:\pythonList\web_python310\lib\site-packages\pymysql\err.py", line 143, in raise_mysql_exception
    raise errorclass(errno, errval)
pymysql.err.DataError: (1366, "Incorrect string value: '\\xF0\\x9F\\x91\\x8D\\xE9\\x9A...' for column 'unchange' at row 1")

The above exception was the direct cause of the following exception:

Traceback (most recent call last):
  File "D:\pythonList\web_python310\lib\site-packages\asgiref\sync.py", line 472, in thread_handler
    raise exc_info[1]
  File "D:\pythonList\web_python310\lib\site-packages\django\core\handlers\exception.py", line 42, in inner
    response = await get_response(request)
  File "D:\pythonList\web_python310\lib\site-packages\django\core\handlers\base.py", line 253, in _get_response_async
    response = await wrapped_callback(
  File "D:\pythonList\web_python310\lib\site-packages\asgiref\sync.py", line 435, in __call__
    ret = await asyncio.wait_for(future, timeout=None)
  File "D:\Python310\lib\asyncio\tasks.py", line 408, in wait_for
    return await fut
  File "D:\Python310\lib\concurrent\futures\thread.py", line 52, in run
    result = self.fn(*self.args, **self.kwargs)
  File "D:\pythonList\web_python310\lib\site-packages\asgiref\sync.py", line 476, in thread_handler
    return func(*args, **kwargs)
  File "D:\pythonList\web_python310\lib\site-packages\django\views\decorators\csrf.py", line 54, in wrapped_view
    return view_func(*args, **kwargs)
  File "D:\pythonList\web_python310\lib\site-packages\django\views\generic\base.py", line 103, in view
    return self.dispatch(request, *args, **kwargs)
  File "D:\pythonList\web_python310\lib\site-packages\rest_framework\views.py", line 509, in dispatch
    response = self.handle_exception(exc)
  File "D:\pythonList\web_python310\lib\site-packages\rest_framework\views.py", line 469, in handle_exception
    self.raise_uncaught_exception(exc)
  File "D:\pythonList\web_python310\lib\site-packages\rest_framework\views.py", line 480, in raise_uncaught_exception
    raise exc
  File "D:\pythonList\web_python310\lib\site-packages\rest_framework\views.py", line 506, in dispatch
    response = handler(request, *args, **kwargs)
  File "C:\Users\Administrator\Desktop\myweb\myweb\saas\views.py", line 438, in post
    serialize.save()
  File "D:\pythonList\web_python310\lib\site-packages\rest_framework\serializers.py", line 212, in save
    self.instance = self.create(validated_data)
  File "D:\pythonList\web_python310\lib\site-packages\rest_framework\serializers.py", line 962, in create
    instance = ModelClass._default_manager.create(**validated_data)
  File "D:\pythonList\web_python310\lib\site-packages\django\db\models\manager.py", line 85, in manager_method
    return getattr(self.get_queryset(), name)(*args, **kwargs)
  File "D:\pythonList\web_python310\lib\site-packages\django\db\models\query.py", line 671, in create
    obj.save(force_insert=True, using=self.db)
  File "D:\pythonList\web_python310\lib\site-packages\django\db\models\base.py", line 812, in save
    self.save_base(
  File "D:\pythonList\web_python310\lib\site-packages\django\db\models\base.py", line 863, in save_base
    updated = self._save_table(
  File "D:\pythonList\web_python310\lib\site-packages\django\db\models\base.py", line 1006, in _save_table
    results = self._do_insert(
  File "D:\pythonList\web_python310\lib\site-packages\django\db\models\base.py", line 1047, in _do_insert
    return manager._insert(
  File "D:\pythonList\web_python310\lib\site-packages\django\db\models\manager.py", line 85, in manager_method
    return getattr(self.get_queryset(), name)(*args, **kwargs)
  File "D:\pythonList\web_python310\lib\site-packages\django\db\models\query.py", line 1791, in _insert
    return query.get_compiler(using=using).execute_sql(returning_fields)
  File "D:\pythonList\web_python310\lib\site-packages\django\db\models\sql\compiler.py", line 1660, in execute_sql
    cursor.execute(sql, params)
  File "D:\pythonList\web_python310\lib\site-packages\django\db\backends\utils.py", line 103, in execute
    return super().execute(sql, params)
  File "D:\pythonList\web_python310\lib\site-packages\django\db\backends\utils.py", line 67, in execute
    return self._execute_with_wrappers(
  File "D:\pythonList\web_python310\lib\site-packages\django\db\backends\utils.py", line 80, in _execute_with_wrappers
    return executor(sql, params, many, context)
  File "D:\pythonList\web_python310\lib\site-packages\django\db\backends\utils.py", line 84, in _execute
    with self.db.wrap_database_errors:
  File "D:\pythonList\web_python310\lib\site-packages\django\db\utils.py", line 91, in __exit__
    raise dj_exc_value.with_traceback(traceback) from exc_value
  File "D:\pythonList\web_python310\lib\site-packages\django\db\backends\utils.py", line 89, in _execute
    return self.cursor.execute(sql, params)
  File "D:\pythonList\web_python310\lib\site-packages\django\db\backends\mysql\base.py", line 75, in execute
    return self.cursor.execute(query, args)
  File "D:\pythonList\web_python310\lib\site-packages\pymysql\cursors.py", line 148, in execute
    result = self._query(query)
  File "D:\pythonList\web_python310\lib\site-packages\pymysql\cursors.py", line 310, in _query
    conn.query(q)
  File "D:\pythonList\web_python310\lib\site-packages\pymysql\connections.py", line 548, in query
    self._affected_rows = self._read_query_result(unbuffered=unbuffered)
  File "D:\pythonList\web_python310\lib\site-packages\pymysql\connections.py", line 775, in _read_query_result
    result.read()
  File "D:\pythonList\web_python310\lib\site-packages\pymysql\connections.py", line 1156, in read
    first_packet = self.connection._read_packet()
  File "D:\pythonList\web_python310\lib\site-packages\pymysql\connections.py", line 725, in _read_packet
    packet.raise_for_error()
  File "D:\pythonList\web_python310\lib\site-packages\pymysql\protocol.py", line 221, in raise_for_error
    err.raise_mysql_exception(self._data)
  File "D:\pythonList\web_python310\lib\site-packages\pymysql\err.py", line 143, in raise_mysql_exception
    raise errorclass(errno, errval)
django.db.utils.DataError: (1366, "Incorrect string value: '\\xF0\\x9F\\x91\\x8D\\xE9\\x9A...' for column 'unchange' at row 1")
[2023-01-05 15:23:43,431] [runserver.py:160] [runserver:log_action] [ERROR]- HTTP POST /cases/ 500 [0.60, 127.0.0.1:54295]
[2023-01-05 15:23:50,570] [runserver.py:147] [runserver:log_action] [INFO]- HTTP GET /cases/ 200 [0.11, 127.0.0.1:54301]
[2023-01-05 15:27:34,958] [runserver.py:147] [runserver:log_action] [INFO]- HTTP GET /cases/?page=2 200 [0.49, 127.0.0.1:54807]
[2023-01-05 15:28:20,024] [runserver.py:147] [runserver:log_action] [INFO]- HTTP GET /cases/?search=shakespeare%2Fnotes%2F6d5a7dae205d%2Ffeatured_comments 200 [0.07, 127.0.0.1:54845]
[2023-01-05 15:28:25,943] [runserver.py:147] [runserver:log_action] [INFO]- HTTP GET /cases/?search= 200 [0.13, 127.0.0.1:54859]
[2023-01-05 15:42:03,685] [runserver.py:147] [runserver:log_action] [INFO]- HTTP GET /cases/ 200 [4.92, 127.0.0.1:56067]
[2023-01-05 15:42:03,825] [runserver.py:147] [runserver:log_action] [INFO]- HTTP GET /projects/ 200 [5.08, 127.0.0.1:56066]
[2023-01-05 15:42:26,930] [fiddlerExe.py:37] [fiddlerExe:getDatas] [INFO]- True
[2023-01-05 15:42:26,981] [runserver.py:147] [runserver:log_action] [INFO]- HTTP POST /dealFiddler/ 200 [0.47, 127.0.0.1:56082]
[2023-01-05 15:42:43,577] [fiddlerExe.py:37] [fiddlerExe:getDatas] [INFO]- True
[2023-01-05 15:42:43,687] [runserver.py:147] [runserver:log_action] [INFO]- HTTP POST /dealFiddler/ 200 [0.12, 127.0.0.1:56092]
[2023-01-05 15:44:59,545] [runserver.py:147] [runserver:log_action] [INFO]- HTTP GET /cases/ 200 [0.57, 127.0.0.1:56144]
[2023-01-05 15:45:12,990] [runserver.py:147] [runserver:log_action] [INFO]- HTTP GET /cases/?page=2 200 [0.24, 127.0.0.1:56156]
[2023-01-05 15:45:58,864] [runserver.py:147] [runserver:log_action] [INFO]- HTTP GET /projects/ 200 [0.13, 127.0.0.1:56189]
[2023-01-05 15:45:58,998] [runserver.py:147] [runserver:log_action] [INFO]- HTTP GET /cases/ 200 [0.26, 127.0.0.1:56190]
[2023-01-05 15:45:59,750] [runserver.py:147] [runserver:log_action] [INFO]- HTTP GET /cases/58 200 [0.28, 127.0.0.1:56195]
[2023-01-05 15:45:59,886] [runserver.py:147] [runserver:log_action] [INFO]- HTTP GET /modules/?project= 200 [0.35, 127.0.0.1:56198]
[2023-01-05 15:46:06,064] [runserver.py:147] [runserver:log_action] [INFO]- HTTP GET /cases/ 200 [0.21, 127.0.0.1:56211]
[2023-01-05 15:46:09,025] [runserver.py:147] [runserver:log_action] [INFO]- HTTP GET /cases/?page=2 200 [0.16, 127.0.0.1:56215]
[2023-01-05 15:46:23,491] [runserver.py:147] [runserver:log_action] [INFO]- HTTP GET /cases/?page=1 200 [0.12, 127.0.0.1:56229]
[2023-01-05 17:42:28,726] [autoreload.py:677] [autoreload:run_with_reloader] [INFO]- Watching for file changes with StatReloader
[2023-01-05 17:43:18,677] [server.py:111] [server:run] [INFO]- HTTP/2 support enabled
[2023-01-05 17:43:18,709] [server.py:122] [server:run] [INFO]- Configuring endpoint tcp:port=8000:interface=127.0.0.1
[2023-01-05 17:43:18,709] [server.py:153] [server:listen_success] [INFO]- Listening on TCP address 127.0.0.1:8000
[2023-01-05 17:44:03,249] [runserver.py:147] [runserver:log_action] [INFO]- HTTP GET /cases/ 200 [10.51, 127.0.0.1:60213]
[2023-01-05 17:44:13,561] [runserver.py:147] [runserver:log_action] [INFO]- HTTP GET /cases/ 200 [0.83, 127.0.0.1:60236]
[2023-01-05 17:44:29,384] [fiddlerExe.py:37] [fiddlerExe:getDatas] [INFO]- True
[2023-01-05 17:44:29,397] [runserver.py:147] [runserver:log_action] [INFO]- HTTP POST /dealFiddler/ 200 [0.09, 127.0.0.1:60261]
[2023-01-05 17:45:11,987] [fiddlerExe.py:37] [fiddlerExe:getDatas] [INFO]- True
[2023-01-05 17:45:12,003] [runserver.py:147] [runserver:log_action] [INFO]- HTTP POST /dealFiddler/ 200 [0.02, 127.0.0.1:60284]
[2023-01-05 17:46:35,949] [fiddlerExe.py:37] [fiddlerExe:getDatas] [INFO]- True
[2023-01-05 17:46:35,960] [runserver.py:147] [runserver:log_action] [INFO]- HTTP POST /dealFiddler/ 200 [0.02, 127.0.0.1:60326]
[2023-01-05 17:47:15,279] [fiddlerExe.py:37] [fiddlerExe:getDatas] [INFO]- True
[2023-01-05 17:47:15,292] [runserver.py:147] [runserver:log_action] [INFO]- HTTP POST /dealFiddler/ 200 [0.02, 127.0.0.1:60353]
[2023-01-05 17:47:51,919] [fiddlerExe.py:37] [fiddlerExe:getDatas] [INFO]- True
[2023-01-05 17:47:51,933] [runserver.py:147] [runserver:log_action] [INFO]- HTTP POST /dealFiddler/ 200 [0.02, 127.0.0.1:60379]
[2023-01-05 17:48:07,659] [fiddlerExe.py:37] [fiddlerExe:getDatas] [INFO]- True
[2023-01-05 17:48:07,671] [runserver.py:147] [runserver:log_action] [INFO]- HTTP POST /dealFiddler/ 200 [0.02, 127.0.0.1:60392]
[2023-01-05 17:52:52,073] [fiddlerExe.py:37] [fiddlerExe:getDatas] [INFO]- True
[2023-01-05 17:52:52,087] [runserver.py:147] [runserver:log_action] [INFO]- HTTP POST /dealFiddler/ 200 [0.10, 127.0.0.1:60633]
[2023-01-05 17:54:39,359] [fiddlerExe.py:37] [fiddlerExe:getDatas] [INFO]- True
[2023-01-05 17:54:39,371] [runserver.py:147] [runserver:log_action] [INFO]- HTTP POST /dealFiddler/ 200 [0.02, 127.0.0.1:60694]
[2023-01-05 17:55:30,769] [runserver.py:147] [runserver:log_action] [INFO]- HTTP POST /cases/ 200 [1.64, 127.0.0.1:60719]
[2023-01-05 17:55:41,893] [runserver.py:147] [runserver:log_action] [INFO]- HTTP GET /cases/ 200 [1.35, 127.0.0.1:60738]
[2023-01-05 17:55:48,061] [runserver.py:147] [runserver:log_action] [INFO]- HTTP GET /cases/?page=2 200 [0.95, 127.0.0.1:60747]
[2023-01-05 18:21:56,008] [runserver.py:147] [runserver:log_action] [INFO]- HTTP GET /cases/ 200 [0.39, 127.0.0.1:61826]
[2023-01-05 18:24:42,121] [runserver.py:147] [runserver:log_action] [INFO]- HTTP GET /cases/ 200 [0.42, 127.0.0.1:61953]
[2023-01-05 18:24:45,209] [runserver.py:147] [runserver:log_action] [INFO]- HTTP GET /cases/ 200 [0.24, 127.0.0.1:61958]
[2023-01-05 18:25:00,181] [fiddlerExe.py:37] [fiddlerExe:getDatas] [INFO]- True
[2023-01-05 18:25:00,277] [runserver.py:147] [runserver:log_action] [INFO]- HTTP POST /dealFiddler/ 200 [0.25, 127.0.0.1:61977]
[2023-01-05 18:25:49,220] [fiddlerExe.py:37] [fiddlerExe:getDatas] [INFO]- True
[2023-01-05 18:25:49,234] [runserver.py:147] [runserver:log_action] [INFO]- HTTP POST /dealFiddler/ 200 [0.03, 127.0.0.1:62015]
[2023-01-05 18:26:22,608] [fiddlerExe.py:37] [fiddlerExe:getDatas] [INFO]- True
[2023-01-05 18:26:22,620] [runserver.py:147] [runserver:log_action] [INFO]- HTTP POST /dealFiddler/ 200 [0.02, 127.0.0.1:62037]
[2023-01-05 18:28:51,523] [fiddlerExe.py:37] [fiddlerExe:getDatas] [INFO]- True
[2023-01-05 18:28:51,532] [runserver.py:147] [runserver:log_action] [INFO]- HTTP POST /dealFiddler/ 200 [0.02, 127.0.0.1:62115]
[2023-01-05 18:29:22,165] [runserver.py:147] [runserver:log_action] [INFO]- HTTP GET /cases/ 200 [0.62, 127.0.0.1:62153]
[2023-01-05 18:30:38,946] [runserver.py:147] [runserver:log_action] [INFO]- HTTP GET /cases/ 200 [1.16, 127.0.0.1:62201]
[2023-01-05 18:30:49,382] [fiddlerExe.py:37] [fiddlerExe:getDatas] [INFO]- True
[2023-01-05 18:30:49,397] [runserver.py:147] [runserver:log_action] [INFO]- HTTP POST /dealFiddler/ 200 [0.07, 127.0.0.1:62219]
[2023-01-05 18:49:17,862] [fiddlerExe.py:37] [fiddlerExe:getDatas] [INFO]- True
[2023-01-05 18:49:17,942] [runserver.py:147] [runserver:log_action] [INFO]- HTTP POST /dealFiddler/ 200 [0.12, 127.0.0.1:62913]
[2023-01-05 18:50:10,773] [fiddlerExe.py:37] [fiddlerExe:getDatas] [INFO]- True
[2023-01-05 18:50:10,784] [runserver.py:147] [runserver:log_action] [INFO]- HTTP POST /dealFiddler/ 200 [0.02, 127.0.0.1:62943]
[2023-01-05 18:51:24,836] [fiddlerExe.py:37] [fiddlerExe:getDatas] [INFO]- True
[2023-01-05 18:51:24,846] [runserver.py:147] [runserver:log_action] [INFO]- HTTP POST /dealFiddler/ 200 [0.02, 127.0.0.1:62983]
[2023-01-05 18:58:39,110] [fiddlerExe.py:37] [fiddlerExe:getDatas] [INFO]- True
[2023-01-05 18:58:39,124] [runserver.py:147] [runserver:log_action] [INFO]- HTTP POST /dealFiddler/ 200 [0.02, 127.0.0.1:63198]
[2023-01-05 19:04:05,548] [fiddlerExe.py:37] [fiddlerExe:getDatas] [INFO]- True
[2023-01-05 19:04:05,592] [runserver.py:147] [runserver:log_action] [INFO]- HTTP POST /dealFiddler/ 200 [0.06, 127.0.0.1:63346]
[2023-01-05 19:04:54,246] [fiddlerExe.py:37] [fiddlerExe:getDatas] [INFO]- True
[2023-01-05 19:04:54,257] [runserver.py:147] [runserver:log_action] [INFO]- HTTP POST /dealFiddler/ 200 [0.02, 127.0.0.1:63373]
[2023-01-05 19:19:12,861] [runserver.py:147] [runserver:log_action] [INFO]- HTTP GET /cases/ 200 [3.23, 127.0.0.1:63737]
[2023-01-05 19:29:43,241] [fiddlerExe.py:37] [fiddlerExe:getDatas] [INFO]- True
[2023-01-05 19:29:43,344] [runserver.py:147] [runserver:log_action] [INFO]- HTTP POST /dealFiddler/ 200 [0.62, 127.0.0.1:64115]
[2023-01-05 19:31:22,949] [fiddlerExe.py:37] [fiddlerExe:getDatas] [INFO]- True
[2023-01-05 19:31:22,960] [runserver.py:147] [runserver:log_action] [INFO]- HTTP POST /dealFiddler/ 200 [0.02, 127.0.0.1:64185]
[2023-01-05 19:32:20,078] [runserver.py:147] [runserver:log_action] [INFO]- HTTP GET /cases/ 200 [2.54, 127.0.0.1:64226]
[2023-01-05 19:32:38,852] [runserver.py:147] [runserver:log_action] [INFO]- HTTP POST /cases/ 200 [5.78, 127.0.0.1:64251]
[2023-01-05 19:32:38,870] [runserver.py:147] [runserver:log_action] [INFO]- HTTP POST /cases/ 200 [5.42, 127.0.0.1:64254]
[2023-01-05 19:32:38,872] [runserver.py:147] [runserver:log_action] [INFO]- HTTP POST /cases/ 200 [5.61, 127.0.0.1:64252]
[2023-01-05 19:32:38,965] [runserver.py:147] [runserver:log_action] [INFO]- HTTP POST /cases/ 200 [5.62, 127.0.0.1:64253]
[2023-01-05 19:32:38,991] [runserver.py:147] [runserver:log_action] [INFO]- HTTP POST /cases/ 200 [5.36, 127.0.0.1:64255]
[2023-01-05 19:32:39,500] [runserver.py:147] [runserver:log_action] [INFO]- HTTP POST /cases/ 200 [6.49, 127.0.0.1:64249]
[2023-01-05 19:32:43,672] [runserver.py:147] [runserver:log_action] [INFO]- HTTP POST /cases/ 200 [4.19, 127.0.0.1:64282]
[2023-01-05 19:32:43,687] [runserver.py:147] [runserver:log_action] [INFO]- HTTP POST /cases/ 200 [4.45, 127.0.0.1:64273]
[2023-01-05 19:32:43,687] [runserver.py:147] [runserver:log_action] [INFO]- HTTP POST /cases/ 200 [4.44, 127.0.0.1:64276]
[2023-01-05 19:32:49,039] [runserver.py:147] [runserver:log_action] [INFO]- HTTP POST /cases/ 200 [9.68, 127.0.0.1:64279]
[2023-01-05 19:32:49,241] [runserver.py:147] [runserver:log_action] [INFO]- HTTP POST /cases/ 200 [9.05, 127.0.0.1:64289]
[2023-01-05 19:32:49,938] [runserver.py:147] [runserver:log_action] [INFO]- HTTP POST /cases/ 200 [5.33, 127.0.0.1:64298]
[2023-01-05 19:32:49,955] [runserver.py:147] [runserver:log_action] [INFO]- HTTP GET /cases/ 200 [5.04, 127.0.0.1:64299]
[2023-01-05 19:32:54,848] [runserver.py:147] [runserver:log_action] [INFO]- HTTP GET /cases/?page=4 200 [0.08, 127.0.0.1:64307]
[2023-01-05 19:33:08,734] [log.py:241] [log:log_response] [ERROR]- Internal Server Error: /cases/
Traceback (most recent call last):
  File "D:\pythonList\web_python310\lib\site-packages\django\db\backends\utils.py", line 89, in _execute
    return self.cursor.execute(sql, params)
  File "D:\pythonList\web_python310\lib\site-packages\django\db\backends\mysql\base.py", line 75, in execute
    return self.cursor.execute(query, args)
  File "D:\pythonList\web_python310\lib\site-packages\pymysql\cursors.py", line 148, in execute
    result = self._query(query)
  File "D:\pythonList\web_python310\lib\site-packages\pymysql\cursors.py", line 310, in _query
    conn.query(q)
  File "D:\pythonList\web_python310\lib\site-packages\pymysql\connections.py", line 548, in query
    self._affected_rows = self._read_query_result(unbuffered=unbuffered)
  File "D:\pythonList\web_python310\lib\site-packages\pymysql\connections.py", line 775, in _read_query_result
    result.read()
  File "D:\pythonList\web_python310\lib\site-packages\pymysql\connections.py", line 1156, in read
    first_packet = self.connection._read_packet()
  File "D:\pythonList\web_python310\lib\site-packages\pymysql\connections.py", line 725, in _read_packet
    packet.raise_for_error()
  File "D:\pythonList\web_python310\lib\site-packages\pymysql\protocol.py", line 221, in raise_for_error
    err.raise_mysql_exception(self._data)
  File "D:\pythonList\web_python310\lib\site-packages\pymysql\err.py", line 143, in raise_mysql_exception
    raise errorclass(errno, errval)
pymysql.err.DataError: (1366, 'Incorrect string value: \'\\xF0\\x9F\\x98\\x84",...\' for column \'unchange\' at row 1')

The above exception was the direct cause of the following exception:

Traceback (most recent call last):
  File "D:\pythonList\web_python310\lib\site-packages\asgiref\sync.py", line 472, in thread_handler
    raise exc_info[1]
  File "D:\pythonList\web_python310\lib\site-packages\django\core\handlers\exception.py", line 42, in inner
    response = await get_response(request)
  File "D:\pythonList\web_python310\lib\site-packages\django\core\handlers\base.py", line 253, in _get_response_async
    response = await wrapped_callback(
  File "D:\pythonList\web_python310\lib\site-packages\asgiref\sync.py", line 435, in __call__
    ret = await asyncio.wait_for(future, timeout=None)
  File "D:\Python310\lib\asyncio\tasks.py", line 408, in wait_for
    return await fut
  File "D:\Python310\lib\concurrent\futures\thread.py", line 52, in run
    result = self.fn(*self.args, **self.kwargs)
  File "D:\pythonList\web_python310\lib\site-packages\asgiref\sync.py", line 476, in thread_handler
    return func(*args, **kwargs)
  File "D:\pythonList\web_python310\lib\site-packages\django\views\decorators\csrf.py", line 54, in wrapped_view
    return view_func(*args, **kwargs)
  File "D:\pythonList\web_python310\lib\site-packages\django\views\generic\base.py", line 103, in view
    return self.dispatch(request, *args, **kwargs)
  File "D:\pythonList\web_python310\lib\site-packages\rest_framework\views.py", line 509, in dispatch
    response = self.handle_exception(exc)
  File "D:\pythonList\web_python310\lib\site-packages\rest_framework\views.py", line 469, in handle_exception
    self.raise_uncaught_exception(exc)
  File "D:\pythonList\web_python310\lib\site-packages\rest_framework\views.py", line 480, in raise_uncaught_exception
    raise exc
  File "D:\pythonList\web_python310\lib\site-packages\rest_framework\views.py", line 506, in dispatch
    response = handler(request, *args, **kwargs)
  File "C:\Users\Administrator\Desktop\myweb\myweb\saas\views.py", line 438, in post
    serialize.save()
  File "D:\pythonList\web_python310\lib\site-packages\rest_framework\serializers.py", line 212, in save
    self.instance = self.create(validated_data)
  File "D:\pythonList\web_python310\lib\site-packages\rest_framework\serializers.py", line 962, in create
    instance = ModelClass._default_manager.create(**validated_data)
  File "D:\pythonList\web_python310\lib\site-packages\django\db\models\manager.py", line 85, in manager_method
    return getattr(self.get_queryset(), name)(*args, **kwargs)
  File "D:\pythonList\web_python310\lib\site-packages\django\db\models\query.py", line 671, in create
    obj.save(force_insert=True, using=self.db)
  File "D:\pythonList\web_python310\lib\site-packages\django\db\models\base.py", line 812, in save
    self.save_base(
  File "D:\pythonList\web_python310\lib\site-packages\django\db\models\base.py", line 863, in save_base
    updated = self._save_table(
  File "D:\pythonList\web_python310\lib\site-packages\django\db\models\base.py", line 1006, in _save_table
    results = self._do_insert(
  File "D:\pythonList\web_python310\lib\site-packages\django\db\models\base.py", line 1047, in _do_insert
    return manager._insert(
  File "D:\pythonList\web_python310\lib\site-packages\django\db\models\manager.py", line 85, in manager_method
    return getattr(self.get_queryset(), name)(*args, **kwargs)
  File "D:\pythonList\web_python310\lib\site-packages\django\db\models\query.py", line 1791, in _insert
    return query.get_compiler(using=using).execute_sql(returning_fields)
  File "D:\pythonList\web_python310\lib\site-packages\django\db\models\sql\compiler.py", line 1660, in execute_sql
    cursor.execute(sql, params)
  File "D:\pythonList\web_python310\lib\site-packages\django\db\backends\utils.py", line 103, in execute
    return super().execute(sql, params)
  File "D:\pythonList\web_python310\lib\site-packages\django\db\backends\utils.py", line 67, in execute
    return self._execute_with_wrappers(
  File "D:\pythonList\web_python310\lib\site-packages\django\db\backends\utils.py", line 80, in _execute_with_wrappers
    return executor(sql, params, many, context)
  File "D:\pythonList\web_python310\lib\site-packages\django\db\backends\utils.py", line 84, in _execute
    with self.db.wrap_database_errors:
  File "D:\pythonList\web_python310\lib\site-packages\django\db\utils.py", line 91, in __exit__
    raise dj_exc_value.with_traceback(traceback) from exc_value
  File "D:\pythonList\web_python310\lib\site-packages\django\db\backends\utils.py", line 89, in _execute
    return self.cursor.execute(sql, params)
  File "D:\pythonList\web_python310\lib\site-packages\django\db\backends\mysql\base.py", line 75, in execute
    return self.cursor.execute(query, args)
  File "D:\pythonList\web_python310\lib\site-packages\pymysql\cursors.py", line 148, in execute
    result = self._query(query)
  File "D:\pythonList\web_python310\lib\site-packages\pymysql\cursors.py", line 310, in _query
    conn.query(q)
  File "D:\pythonList\web_python310\lib\site-packages\pymysql\connections.py", line 548, in query
    self._affected_rows = self._read_query_result(unbuffered=unbuffered)
  File "D:\pythonList\web_python310\lib\site-packages\pymysql\connections.py", line 775, in _read_query_result
    result.read()
  File "D:\pythonList\web_python310\lib\site-packages\pymysql\connections.py", line 1156, in read
    first_packet = self.connection._read_packet()
  File "D:\pythonList\web_python310\lib\site-packages\pymysql\connections.py", line 725, in _read_packet
    packet.raise_for_error()
  File "D:\pythonList\web_python310\lib\site-packages\pymysql\protocol.py", line 221, in raise_for_error
    err.raise_mysql_exception(self._data)
  File "D:\pythonList\web_python310\lib\site-packages\pymysql\err.py", line 143, in raise_mysql_exception
    raise errorclass(errno, errval)
django.db.utils.DataError: (1366, 'Incorrect string value: \'\\xF0\\x9F\\x98\\x84",...\' for column \'unchange\' at row 1')
[2023-01-05 19:33:09,951] [runserver.py:160] [runserver:log_action] [ERROR]- HTTP POST /cases/ 500 [30.71, 127.0.0.1:64277]
[2023-01-05 19:33:42,040] [runserver.py:147] [runserver:log_action] [INFO]- HTTP GET /cases/?search=shakespeare%2Fnotes%2F6d5a7dae205d%2Ffeatured_comments 200 [0.42, 127.0.0.1:64338]
[2023-01-05 19:34:29,691] [runserver.py:147] [runserver:log_action] [INFO]- HTTP GET /cases/?search= 200 [0.10, 127.0.0.1:64359]
[2023-01-05 19:34:38,904] [runserver.py:147] [runserver:log_action] [INFO]- HTTP GET /cases/?size=200 200 [0.20, 127.0.0.1:64368]
[2023-01-05 19:34:46,307] [runserver.py:147] [runserver:log_action] [INFO]- HTTP DELETE /cases/53 200 [1.07, 127.0.0.1:64389]
[2023-01-05 19:34:46,307] [runserver.py:147] [runserver:log_action] [INFO]- HTTP DELETE /cases/51 200 [1.07, 127.0.0.1:64388]
[2023-01-05 19:34:46,307] [runserver.py:147] [runserver:log_action] [INFO]- HTTP DELETE /cases/50 200 [1.08, 127.0.0.1:64387]
[2023-01-05 19:34:46,307] [runserver.py:147] [runserver:log_action] [INFO]- HTTP DELETE /cases/52 200 [1.07, 127.0.0.1:64390]
[2023-01-05 19:34:46,414] [runserver.py:147] [runserver:log_action] [INFO]- HTTP DELETE /cases/49 200 [1.19, 127.0.0.1:64386]
[2023-01-05 19:34:46,521] [runserver.py:147] [runserver:log_action] [INFO]- HTTP DELETE /cases/56 200 [1.25, 127.0.0.1:64393]
[2023-01-05 19:34:47,082] [runserver.py:147] [runserver:log_action] [INFO]- HTTP DELETE /cases/57 200 [0.45, 127.0.0.1:64409]
[2023-01-05 19:34:47,119] [runserver.py:147] [runserver:log_action] [INFO]- HTTP DELETE /cases/48 200 [0.48, 127.0.0.1:64411]
[2023-01-05 19:34:47,161] [runserver.py:147] [runserver:log_action] [INFO]- HTTP DELETE /cases/60 200 [0.52, 127.0.0.1:64412]
[2023-01-05 19:34:47,238] [runserver.py:147] [runserver:log_action] [INFO]- HTTP DELETE /cases/61 200 [0.51, 127.0.0.1:64418]
[2023-01-05 19:34:47,249] [runserver.py:147] [runserver:log_action] [INFO]- HTTP DELETE /cases/62 200 [0.34, 127.0.0.1:64421]
[2023-01-05 19:34:47,251] [runserver.py:147] [runserver:log_action] [INFO]- HTTP DELETE /cases/59 200 [0.61, 127.0.0.1:64410]
[2023-01-05 19:34:47,618] [runserver.py:147] [runserver:log_action] [INFO]- HTTP DELETE /cases/63 200 [0.15, 127.0.0.1:64432]
[2023-01-05 19:34:47,622] [runserver.py:147] [runserver:log_action] [INFO]- HTTP DELETE /cases/64 200 [0.15, 127.0.0.1:64431]
[2023-01-05 19:34:47,628] [runserver.py:147] [runserver:log_action] [INFO]- HTTP DELETE /cases/65 200 [0.15, 127.0.0.1:64434]
[2023-01-05 19:34:47,681] [runserver.py:147] [runserver:log_action] [INFO]- HTTP DELETE /cases/67 200 [0.12, 127.0.0.1:64442]
[2023-01-05 19:34:47,736] [runserver.py:147] [runserver:log_action] [INFO]- HTTP DELETE /cases/68 200 [0.16, 127.0.0.1:64443]
[2023-01-05 19:34:47,741] [runserver.py:147] [runserver:log_action] [INFO]- HTTP DELETE /cases/66 200 [0.18, 127.0.0.1:64441]
[2023-01-05 19:34:48,086] [runserver.py:147] [runserver:log_action] [INFO]- HTTP DELETE /cases/69 200 [0.16, 127.0.0.1:64454]
[2023-01-05 19:34:48,091] [runserver.py:147] [runserver:log_action] [INFO]- HTTP DELETE /cases/72 200 [0.09, 127.0.0.1:64463]
[2023-01-05 19:34:48,091] [runserver.py:147] [runserver:log_action] [INFO]- HTTP DELETE /cases/71 200 [0.14, 127.0.0.1:64459]
[2023-01-05 19:34:48,091] [runserver.py:147] [runserver:log_action] [INFO]- HTTP DELETE /cases/70 200 [0.14, 127.0.0.1:64458]
[2023-01-05 19:34:48,255] [runserver.py:147] [runserver:log_action] [INFO]- HTTP DELETE /cases/73 200 [0.21, 127.0.0.1:64466]
[2023-01-05 19:34:48,284] [runserver.py:147] [runserver:log_action] [INFO]- HTTP DELETE /cases/74 200 [0.22, 127.0.0.1:64468]
[2023-01-05 19:34:48,591] [runserver.py:147] [runserver:log_action] [INFO]- HTTP DELETE /cases/75 200 [0.19, 127.0.0.1:64478]
[2023-01-05 19:34:48,706] [runserver.py:147] [runserver:log_action] [INFO]- HTTP DELETE /cases/78 200 [0.28, 127.0.0.1:64483]
[2023-01-05 19:34:48,734] [runserver.py:147] [runserver:log_action] [INFO]- HTTP DELETE /cases/77 200 [0.31, 127.0.0.1:64482]
[2023-01-05 19:34:48,735] [runserver.py:147] [runserver:log_action] [INFO]- HTTP DELETE /cases/79 200 [0.16, 127.0.0.1:64490]
[2023-01-05 19:34:48,738] [runserver.py:147] [runserver:log_action] [INFO]- HTTP DELETE /cases/76 200 [0.31, 127.0.0.1:64484]
[2023-01-05 19:34:48,829] [runserver.py:147] [runserver:log_action] [INFO]- HTTP DELETE /cases/54 200 [0.23, 127.0.0.1:64493]
[2023-01-05 19:34:49,001] [runserver.py:147] [runserver:log_action] [INFO]- HTTP DELETE /cases/55 200 [0.09, 127.0.0.1:64498]
[2023-01-05 19:34:49,126] [runserver.py:147] [runserver:log_action] [INFO]- HTTP DELETE /cases/58 200 [0.11, 127.0.0.1:64501]
[2023-01-05 19:34:50,637] [runserver.py:147] [runserver:log_action] [INFO]- HTTP GET /cases/ 200 [0.02, 127.0.0.1:64507]
[2023-01-05 19:34:55,665] [runserver.py:147] [runserver:log_action] [INFO]- HTTP POST /cases/ 200 [0.20, 127.0.0.1:64526]
[2023-01-05 19:34:55,676] [runserver.py:147] [runserver:log_action] [INFO]- HTTP POST /cases/ 200 [0.20, 127.0.0.1:64530]
[2023-01-05 19:34:55,680] [runserver.py:147] [runserver:log_action] [INFO]- HTTP POST /cases/ 200 [0.21, 127.0.0.1:64527]
[2023-01-05 19:34:55,684] [runserver.py:147] [runserver:log_action] [INFO]- HTTP POST /cases/ 200 [0.21, 127.0.0.1:64529]
[2023-01-05 19:34:55,713] [runserver.py:147] [runserver:log_action] [INFO]- HTTP POST /cases/ 200 [0.23, 127.0.0.1:64531]
[2023-01-05 19:34:55,716] [runserver.py:147] [runserver:log_action] [INFO]- HTTP POST /cases/ 200 [0.24, 127.0.0.1:64528]
[2023-01-05 19:34:56,121] [runserver.py:147] [runserver:log_action] [INFO]- HTTP POST /cases/ 200 [0.14, 127.0.0.1:64545]
[2023-01-05 19:34:56,138] [runserver.py:147] [runserver:log_action] [INFO]- HTTP POST /cases/ 200 [0.14, 127.0.0.1:64547]
[2023-01-05 19:34:56,145] [runserver.py:147] [runserver:log_action] [INFO]- HTTP POST /cases/ 200 [0.14, 127.0.0.1:64552]
[2023-01-05 19:34:56,269] [runserver.py:147] [runserver:log_action] [INFO]- HTTP POST /cases/ 200 [0.22, 127.0.0.1:64555]
[2023-01-05 19:34:56,316] [runserver.py:147] [runserver:log_action] [INFO]- HTTP POST /cases/ 200 [0.26, 127.0.0.1:64557]
[2023-01-05 19:34:56,488] [log.py:241] [log:log_response] [ERROR]- Internal Server Error: /cases/
Traceback (most recent call last):
  File "D:\pythonList\web_python310\lib\site-packages\django\db\backends\utils.py", line 89, in _execute
    return self.cursor.execute(sql, params)
  File "D:\pythonList\web_python310\lib\site-packages\django\db\backends\mysql\base.py", line 75, in execute
    return self.cursor.execute(query, args)
  File "D:\pythonList\web_python310\lib\site-packages\pymysql\cursors.py", line 148, in execute
    result = self._query(query)
  File "D:\pythonList\web_python310\lib\site-packages\pymysql\cursors.py", line 310, in _query
    conn.query(q)
  File "D:\pythonList\web_python310\lib\site-packages\pymysql\connections.py", line 548, in query
    self._affected_rows = self._read_query_result(unbuffered=unbuffered)
  File "D:\pythonList\web_python310\lib\site-packages\pymysql\connections.py", line 775, in _read_query_result
    result.read()
  File "D:\pythonList\web_python310\lib\site-packages\pymysql\connections.py", line 1156, in read
    first_packet = self.connection._read_packet()
  File "D:\pythonList\web_python310\lib\site-packages\pymysql\connections.py", line 725, in _read_packet
    packet.raise_for_error()
  File "D:\pythonList\web_python310\lib\site-packages\pymysql\protocol.py", line 221, in raise_for_error
    err.raise_mysql_exception(self._data)
  File "D:\pythonList\web_python310\lib\site-packages\pymysql\err.py", line 143, in raise_mysql_exception
    raise errorclass(errno, errval)
pymysql.err.DataError: (1366, 'Incorrect string value: \'\\xF0\\x9F\\x98\\x84",...\' for column \'unchange\' at row 1')

The above exception was the direct cause of the following exception:

Traceback (most recent call last):
  File "D:\pythonList\web_python310\lib\site-packages\asgiref\sync.py", line 472, in thread_handler
    raise exc_info[1]
  File "D:\pythonList\web_python310\lib\site-packages\django\core\handlers\exception.py", line 42, in inner
    response = await get_response(request)
  File "D:\pythonList\web_python310\lib\site-packages\django\core\handlers\base.py", line 253, in _get_response_async
    response = await wrapped_callback(
  File "D:\pythonList\web_python310\lib\site-packages\asgiref\sync.py", line 435, in __call__
    ret = await asyncio.wait_for(future, timeout=None)
  File "D:\Python310\lib\asyncio\tasks.py", line 408, in wait_for
    return await fut
  File "D:\Python310\lib\concurrent\futures\thread.py", line 52, in run
    result = self.fn(*self.args, **self.kwargs)
  File "D:\pythonList\web_python310\lib\site-packages\asgiref\sync.py", line 476, in thread_handler
    return func(*args, **kwargs)
  File "D:\pythonList\web_python310\lib\site-packages\django\views\decorators\csrf.py", line 54, in wrapped_view
    return view_func(*args, **kwargs)
  File "D:\pythonList\web_python310\lib\site-packages\django\views\generic\base.py", line 103, in view
    return self.dispatch(request, *args, **kwargs)
  File "D:\pythonList\web_python310\lib\site-packages\rest_framework\views.py", line 509, in dispatch
    response = self.handle_exception(exc)
  File "D:\pythonList\web_python310\lib\site-packages\rest_framework\views.py", line 469, in handle_exception
    self.raise_uncaught_exception(exc)
  File "D:\pythonList\web_python310\lib\site-packages\rest_framework\views.py", line 480, in raise_uncaught_exception
    raise exc
  File "D:\pythonList\web_python310\lib\site-packages\rest_framework\views.py", line 506, in dispatch
    response = handler(request, *args, **kwargs)
  File "C:\Users\Administrator\Desktop\myweb\myweb\saas\views.py", line 438, in post
    serialize.save()
  File "D:\pythonList\web_python310\lib\site-packages\rest_framework\serializers.py", line 212, in save
    self.instance = self.create(validated_data)
  File "D:\pythonList\web_python310\lib\site-packages\rest_framework\serializers.py", line 962, in create
    instance = ModelClass._default_manager.create(**validated_data)
  File "D:\pythonList\web_python310\lib\site-packages\django\db\models\manager.py", line 85, in manager_method
    return getattr(self.get_queryset(), name)(*args, **kwargs)
  File "D:\pythonList\web_python310\lib\site-packages\django\db\models\query.py", line 671, in create
    obj.save(force_insert=True, using=self.db)
  File "D:\pythonList\web_python310\lib\site-packages\django\db\models\base.py", line 812, in save
    self.save_base(
  File "D:\pythonList\web_python310\lib\site-packages\django\db\models\base.py", line 863, in save_base
    updated = self._save_table(
  File "D:\pythonList\web_python310\lib\site-packages\django\db\models\base.py", line 1006, in _save_table
    results = self._do_insert(
  File "D:\pythonList\web_python310\lib\site-packages\django\db\models\base.py", line 1047, in _do_insert
    return manager._insert(
  File "D:\pythonList\web_python310\lib\site-packages\django\db\models\manager.py", line 85, in manager_method
    return getattr(self.get_queryset(), name)(*args, **kwargs)
  File "D:\pythonList\web_python310\lib\site-packages\django\db\models\query.py", line 1791, in _insert
    return query.get_compiler(using=using).execute_sql(returning_fields)
  File "D:\pythonList\web_python310\lib\site-packages\django\db\models\sql\compiler.py", line 1660, in execute_sql
    cursor.execute(sql, params)
  File "D:\pythonList\web_python310\lib\site-packages\django\db\backends\utils.py", line 103, in execute
    return super().execute(sql, params)
  File "D:\pythonList\web_python310\lib\site-packages\django\db\backends\utils.py", line 67, in execute
    return self._execute_with_wrappers(
  File "D:\pythonList\web_python310\lib\site-packages\django\db\backends\utils.py", line 80, in _execute_with_wrappers
    return executor(sql, params, many, context)
  File "D:\pythonList\web_python310\lib\site-packages\django\db\backends\utils.py", line 84, in _execute
    with self.db.wrap_database_errors:
  File "D:\pythonList\web_python310\lib\site-packages\django\db\utils.py", line 91, in __exit__
    raise dj_exc_value.with_traceback(traceback) from exc_value
  File "D:\pythonList\web_python310\lib\site-packages\django\db\backends\utils.py", line 89, in _execute
    return self.cursor.execute(sql, params)
  File "D:\pythonList\web_python310\lib\site-packages\django\db\backends\mysql\base.py", line 75, in execute
    return self.cursor.execute(query, args)
  File "D:\pythonList\web_python310\lib\site-packages\pymysql\cursors.py", line 148, in execute
    result = self._query(query)
  File "D:\pythonList\web_python310\lib\site-packages\pymysql\cursors.py", line 310, in _query
    conn.query(q)
  File "D:\pythonList\web_python310\lib\site-packages\pymysql\connections.py", line 548, in query
    self._affected_rows = self._read_query_result(unbuffered=unbuffered)
  File "D:\pythonList\web_python310\lib\site-packages\pymysql\connections.py", line 775, in _read_query_result
    result.read()
  File "D:\pythonList\web_python310\lib\site-packages\pymysql\connections.py", line 1156, in read
    first_packet = self.connection._read_packet()
  File "D:\pythonList\web_python310\lib\site-packages\pymysql\connections.py", line 725, in _read_packet
    packet.raise_for_error()
  File "D:\pythonList\web_python310\lib\site-packages\pymysql\protocol.py", line 221, in raise_for_error
    err.raise_mysql_exception(self._data)
  File "D:\pythonList\web_python310\lib\site-packages\pymysql\err.py", line 143, in raise_mysql_exception
    raise errorclass(errno, errval)
django.db.utils.DataError: (1366, 'Incorrect string value: \'\\xF0\\x9F\\x98\\x84",...\' for column \'unchange\' at row 1')
[2023-01-05 19:34:56,503] [runserver.py:160] [runserver:log_action] [ERROR]- HTTP POST /cases/ 500 [0.50, 127.0.0.1:64550]
[2023-01-05 19:34:56,684] [runserver.py:147] [runserver:log_action] [INFO]- HTTP POST /cases/ 200 [0.20, 127.0.0.1:64565]
[2023-01-05 19:35:08,427] [runserver.py:147] [runserver:log_action] [INFO]- HTTP GET /cases/ 200 [0.10, 127.0.0.1:64574]
[2023-01-05 19:35:13,930] [runserver.py:147] [runserver:log_action] [INFO]- HTTP GET /cases/?size=500 200 [0.12, 127.0.0.1:64583]
[2023-01-05 19:36:55,366] [runserver.py:147] [runserver:log_action] [INFO]- HTTP GET /cases/?search=shakespeare%2Fnotes%2F6d5a7dae205d%2Ffeatured_comments 200 [0.11, 127.0.0.1:64629]
[2023-01-05 19:37:02,087] [runserver.py:147] [runserver:log_action] [INFO]- HTTP GET /cases/?search= 200 [0.08, 127.0.0.1:64638]
[2023-01-05 19:37:46,812] [runserver.py:147] [runserver:log_action] [INFO]- HTTP GET /cases/?search=shakespeare%2Fnotes%2F6d5a7dae205d%2Frecommendations 200 [0.12, 127.0.0.1:64665]
[2023-01-05 19:37:50,442] [runserver.py:147] [runserver:log_action] [INFO]- HTTP GET /cases/?search= 200 [0.11, 127.0.0.1:64668]
[2023-01-05 19:38:13,967] [runserver.py:147] [runserver:log_action] [INFO]- HTTP GET /cases/?search=shakespeare%2Fnotes%2F108710063%2Fuser_notes 200 [0.12, 127.0.0.1:64685]
[2023-01-05 19:38:20,772] [runserver.py:147] [runserver:log_action] [INFO]- HTTP GET /cases/?search= 200 [0.09, 127.0.0.1:64695]
[2023-01-05 19:39:24,322] [runserver.py:147] [runserver:log_action] [INFO]- HTTP GET /cases/ 200 [0.56, 127.0.0.1:64744]
[2023-01-05 20:47:11,472] [runserver.py:147] [runserver:log_action] [INFO]- HTTP GET /cases/?size=500 200 [0.22, 127.0.0.1:53453]
[2023-01-05 20:48:17,791] [runserver.py:147] [runserver:log_action] [INFO]- HTTP GET /cases/?search=shakespeare%2Fnotes%2F105730034%2Fcomments 200 [0.12, 127.0.0.1:53484]
[2023-01-05 20:49:28,166] [runserver.py:147] [runserver:log_action] [INFO]- HTTP POST /cases/ 200 [0.12, 127.0.0.1:53529]
[2023-01-05 20:49:31,368] [runserver.py:147] [runserver:log_action] [INFO]- HTTP GET /cases/ 200 [0.10, 127.0.0.1:53535]
[2023-01-05 20:49:34,640] [runserver.py:147] [runserver:log_action] [INFO]- HTTP GET /cases/?page=2 200 [0.07, 127.0.0.1:53543]
[2023-01-05 20:49:46,187] [runserver.py:147] [runserver:log_action] [INFO]- HTTP GET /cases/?size=500 200 [0.17, 127.0.0.1:53559]
[2023-01-05 20:49:46,187] [runserver.py:147] [runserver:log_action] [INFO]- HTTP GET /cases/?size=500&page=1 200 [0.17, 127.0.0.1:53558]
[2023-01-05 20:50:30,109] [runserver.py:147] [runserver:log_action] [INFO]- HTTP GET /cases/?size=10 200 [0.07, 127.0.0.1:53584]
[2023-01-05 20:50:34,087] [runserver.py:147] [runserver:log_action] [INFO]- HTTP GET /cases/?size=10&page=2 200 [0.05, 127.0.0.1:53591]
