[2023-01-10 15:07:42,546] [autoreload.py:677] [autoreload:run_with_reloader] [INFO]- Watching for file changes with StatReloader
[2023-01-10 15:07:52,782] [server.py:111] [server:run] [INFO]- HTTP/2 support enabled
[2023-01-10 15:07:52,782] [server.py:122] [server:run] [INFO]- Configuring endpoint tcp:port=8000:interface=127.0.0.1
[2023-01-10 15:07:52,782] [server.py:153] [server:listen_success] [INFO]- Listening on TCP address 127.0.0.1:8000
[2023-01-10 15:08:22,488] [log.py:241] [log:log_response] [WARNING]- Not Found: /
[2023-01-10 15:08:22,489] [runserver.py:155] [runserver:log_action] [WARNING]- HTTP GET / 404 [0.24, 127.0.0.1:55357]
[2023-01-10 15:08:22,845] [log.py:241] [log:log_response] [WARNING]- Not Found: /favicon.ico
[2023-01-10 15:08:22,847] [runserver.py:155] [runserver:log_action] [WARNING]- HTTP GET /favicon.ico 404 [0.05, 127.0.0.1:55357]
[2023-01-10 15:08:29,870] [runserver.py:147] [runserver:log_action] [INFO]- HTTP GET /cases/ 200 [0.92, 127.0.0.1:55357]
[2023-01-10 15:11:16,871] [fiddlerExe.py:37] [fiddlerExe:getDatas] [INFO]- True
[2023-01-10 15:11:16,886] [runserver.py:147] [runserver:log_action] [INFO]- HTTP POST /dealFiddler/ 200 [0.02, 127.0.0.1:55402]
[2023-01-10 15:12:28,413] [fiddlerExe.py:37] [fiddlerExe:getDatas] [INFO]- True
[2023-01-10 15:12:28,444] [runserver.py:147] [runserver:log_action] [INFO]- HTTP POST /dealFiddlerNotSql/ 200 [0.03, 127.0.0.1:55420]
[2023-01-10 15:12:54,672] [fiddlerExe.py:37] [fiddlerExe:getDatas] [INFO]- True
[2023-01-10 15:12:54,688] [runserver.py:147] [runserver:log_action] [INFO]- HTTP POST /dealFiddler/ 200 [0.02, 127.0.0.1:55430]
[2023-01-10 15:12:59,918] [fiddlerExe.py:37] [fiddlerExe:getDatas] [INFO]- True
[2023-01-10 15:12:59,933] [runserver.py:147] [runserver:log_action] [INFO]- HTTP POST /dealFiddler/ 200 [0.02, 127.0.0.1:55435]
[2023-01-10 15:13:16,407] [fiddlerExe.py:37] [fiddlerExe:getDatas] [INFO]- True
[2023-01-10 15:13:16,469] [runserver.py:147] [runserver:log_action] [INFO]- HTTP POST /dealFiddlerNotSql/ 200 [0.08, 127.0.0.1:55441]
[2023-01-10 15:13:39,272] [runserver.py:147] [runserver:log_action] [INFO]- HTTP GET /cases/ 200 [0.20, 127.0.0.1:55448]
[2023-01-10 15:20:04,691] [fiddlerExe.py:37] [fiddlerExe:getDatas] [INFO]- True
[2023-01-10 15:20:04,703] [runserver.py:147] [runserver:log_action] [INFO]- HTTP POST /dealFiddler/ 200 [0.19, 127.0.0.1:55731]
[2023-01-10 15:27:10,594] [fiddlerExe.py:37] [fiddlerExe:getDatas] [INFO]- True
[2023-01-10 15:27:10,608] [runserver.py:147] [runserver:log_action] [INFO]- HTTP POST /dealFiddler/ 200 [0.16, 127.0.0.1:56216]
[2023-01-10 15:27:16,475] [fiddlerExe.py:37] [fiddlerExe:getDatas] [INFO]- True
[2023-01-10 15:27:17,998] [runserver.py:147] [runserver:log_action] [INFO]- HTTP POST /dealFiddlerNotSql/ 200 [1.53, 127.0.0.1:56227]
[2023-01-10 15:27:25,883] [fiddlerExe.py:37] [fiddlerExe:getDatas] [INFO]- True
[2023-01-10 15:27:25,954] [runserver.py:147] [runserver:log_action] [INFO]- HTTP POST /dealFiddlerNotSql/ 200 [0.08, 127.0.0.1:56237]
[2023-01-10 15:27:49,349] [runserver.py:147] [runserver:log_action] [INFO]- HTTP GET /cases/ 200 [1.79, 127.0.0.1:56255]
[2023-01-10 15:43:24,163] [runserver.py:147] [runserver:log_action] [INFO]- HTTP GET /cases/ 200 [0.52, 127.0.0.1:57201]
[2023-01-10 15:46:36,194] [autoreload.py:677] [autoreload:run_with_reloader] [INFO]- Watching for file changes with StatReloader
[2023-01-10 15:46:40,158] [server.py:111] [server:run] [INFO]- HTTP/2 support enabled
[2023-01-10 15:46:40,158] [server.py:122] [server:run] [INFO]- Configuring endpoint tcp:port=8000:interface=127.0.0.1
[2023-01-10 15:46:40,158] [server.py:153] [server:listen_success] [INFO]- Listening on TCP address 127.0.0.1:8000
[2023-01-10 15:46:47,493] [fiddlerExe.py:37] [fiddlerExe:getDatas] [INFO]- True
[2023-01-10 15:50:02,528] [fiddlerExe.py:37] [fiddlerExe:getDatas] [INFO]- True
[2023-01-10 15:50:02,558] [runserver.py:147] [runserver:log_action] [INFO]- HTTP POST /dealFiddler/ 200 [0.05, 127.0.0.1:57344]
[2023-01-10 15:50:06,653] [fiddlerExe.py:37] [fiddlerExe:getDatas] [INFO]- True
[2023-01-10 15:50:17,162] [fiddlerExe.py:37] [fiddlerExe:getDatas] [INFO]- True
[2023-01-10 15:50:30,729] [fiddlerExe.py:37] [fiddlerExe:getDatas] [INFO]- True
[2023-01-10 15:50:37,879] [fiddlerExe.py:37] [fiddlerExe:getDatas] [INFO]- True
[2023-01-10 15:50:54,037] [autoreload.py:677] [autoreload:run_with_reloader] [INFO]- Watching for file changes with StatReloader
[2023-01-10 15:50:54,523] [server.py:111] [server:run] [INFO]- HTTP/2 support enabled
[2023-01-10 15:50:54,523] [server.py:122] [server:run] [INFO]- Configuring endpoint tcp:port=8000:interface=127.0.0.1
[2023-01-10 15:50:54,523] [server.py:153] [server:listen_success] [INFO]- Listening on TCP address 127.0.0.1:8000
[2023-01-10 15:51:22,323] [fiddlerExe.py:37] [fiddlerExe:getDatas] [INFO]- True
[2023-01-10 15:51:22,392] [runserver.py:147] [runserver:log_action] [INFO]- HTTP POST /dealFiddlerNotSql/ 200 [0.09, 127.0.0.1:57402]
[2023-01-10 15:54:12,409] [runserver.py:147] [runserver:log_action] [INFO]- HTTP DELETE /cases/94 200 [1.60, 127.0.0.1:57548]
[2023-01-10 15:54:22,132] [fiddlerExe.py:37] [fiddlerExe:getDatas] [INFO]- True
[2023-01-10 15:54:22,291] [runserver.py:147] [runserver:log_action] [INFO]- HTTP POST /dealFiddlerNotSql/ 200 [0.30, 127.0.0.1:57560]
[2023-01-10 16:43:38,695] [runserver.py:147] [runserver:log_action] [INFO]- HTTP GET /cases/ 200 [0.14, 127.0.0.1:58041]
[2023-01-10 16:44:03,774] [runserver.py:147] [runserver:log_action] [INFO]- HTTP DELETE /cases/95 200 [0.25, 127.0.0.1:58066]
[2023-01-10 16:45:42,696] [runserver.py:147] [runserver:log_action] [INFO]- HTTP GET /cases/ 200 [0.19, 127.0.0.1:58133]
[2023-01-10 16:45:43,055] [runserver.py:147] [runserver:log_action] [INFO]- HTTP GET /cases/ 200 [0.16, 127.0.0.1:58139]
[2023-01-10 16:45:52,822] [runserver.py:147] [runserver:log_action] [INFO]- HTTP DELETE /cases/96 200 [0.09, 127.0.0.1:58149]
[2023-01-10 16:45:54,113] [runserver.py:147] [runserver:log_action] [INFO]- HTTP GET /cases/ 200 [0.23, 127.0.0.1:58158]
[2023-01-10 16:46:27,795] [fiddlerExe.py:37] [fiddlerExe:getDatas] [INFO]- True
[2023-01-10 16:46:27,870] [runserver.py:147] [runserver:log_action] [INFO]- HTTP POST /dealFiddlerNotSql/ 200 [0.21, 127.0.0.1:58178]
[2023-01-10 16:47:09,745] [fiddlerExe.py:37] [fiddlerExe:getDatas] [INFO]- True
[2023-01-10 16:47:09,842] [runserver.py:147] [runserver:log_action] [INFO]- HTTP POST /dealFiddlerNotSql/ 200 [0.11, 127.0.0.1:58208]
[2023-01-10 18:38:25,934] [runserver.py:147] [runserver:log_action] [INFO]- HTTP GET /cases/ 200 [57.78, 127.0.0.1:60241]
[2023-01-10 18:38:26,607] [runserver.py:147] [runserver:log_action] [INFO]- HTTP GET /cases/ 200 [109.89, 127.0.0.1:60203]
[2023-01-10 18:38:26,608] [runserver.py:147] [runserver:log_action] [INFO]- HTTP GET /cases/ 200 [24.72, 127.0.0.1:60262]
[2023-01-10 18:38:26,616] [runserver.py:147] [runserver:log_action] [INFO]- HTTP GET /cases/ 200 [102.63, 127.0.0.1:60212]
[2023-01-10 18:39:07,901] [fiddlerExe.py:37] [fiddlerExe:getDatas] [INFO]- True
[2023-01-10 18:39:08,096] [runserver.py:147] [runserver:log_action] [INFO]- HTTP POST /dealFiddler/ 200 [0.49, 127.0.0.1:60300]
[2023-01-10 19:09:07,545] [autoreload.py:266] [autoreload:trigger_reload] [INFO]- C:\Users\Administrator\Desktop\myweb\myweb\saas\views.py changed, reloading.
[2023-01-10 19:10:13,385] [autoreload.py:677] [autoreload:run_with_reloader] [INFO]- Watching for file changes with StatReloader
[2023-01-10 19:10:21,998] [server.py:111] [server:run] [INFO]- HTTP/2 support enabled
[2023-01-10 19:10:21,998] [server.py:122] [server:run] [INFO]- Configuring endpoint tcp:port=8000:interface=127.0.0.1
[2023-01-10 19:10:21,998] [server.py:153] [server:listen_success] [INFO]- Listening on TCP address 127.0.0.1:8000
[2023-01-10 19:11:48,774] [fiddlerExe.py:37] [fiddlerExe:getDatas] [INFO]- True
[2023-01-10 19:11:48,821] [runserver.py:147] [runserver:log_action] [INFO]- HTTP POST /dealFiddlerOnly/ 200 [0.23, 127.0.0.1:61433]
[2023-01-10 19:12:00,639] [fiddlerExe.py:37] [fiddlerExe:getDatas] [INFO]- True
[2023-01-10 19:12:01,365] [runserver.py:147] [runserver:log_action] [INFO]- HTTP POST /dealFiddlerNotSql/ 200 [0.73, 127.0.0.1:61441]
[2023-01-10 19:12:43,104] [fiddlerExe.py:37] [fiddlerExe:getDatas] [INFO]- True
[2023-01-10 19:12:43,529] [runserver.py:147] [runserver:log_action] [INFO]- HTTP POST /dealFiddlerNotSql/ 200 [0.57, 127.0.0.1:61476]
[2023-01-10 19:12:57,087] [fiddlerExe.py:37] [fiddlerExe:getDatas] [INFO]- True
[2023-01-10 19:12:57,388] [runserver.py:147] [runserver:log_action] [INFO]- HTTP POST /dealFiddlerNotSql/ 200 [0.31, 127.0.0.1:61486]
[2023-01-10 19:13:07,089] [fiddlerExe.py:37] [fiddlerExe:getDatas] [INFO]- True
[2023-01-10 19:13:07,102] [runserver.py:147] [runserver:log_action] [INFO]- HTTP POST /dealFiddler/ 200 [0.03, 127.0.0.1:61496]
[2023-01-10 19:14:16,097] [fiddlerExe.py:37] [fiddlerExe:getDatas] [INFO]- True
[2023-01-10 19:14:16,109] [runserver.py:147] [runserver:log_action] [INFO]- HTTP POST /dealFiddler/ 200 [0.02, 127.0.0.1:61527]
[2023-01-10 19:14:32,169] [runserver.py:147] [runserver:log_action] [INFO]- HTTP POST /cases/ 200 [3.42, 127.0.0.1:61545]
[2023-01-10 19:14:32,169] [runserver.py:147] [runserver:log_action] [INFO]- HTTP POST /cases/ 200 [3.40, 127.0.0.1:61546]
[2023-01-10 19:14:32,169] [runserver.py:147] [runserver:log_action] [INFO]- HTTP POST /cases/ 200 [3.40, 127.0.0.1:61547]
[2023-01-10 19:14:32,169] [runserver.py:147] [runserver:log_action] [INFO]- HTTP POST /cases/ 200 [3.40, 127.0.0.1:61549]
[2023-01-10 19:14:32,169] [runserver.py:147] [runserver:log_action] [INFO]- HTTP POST /cases/ 200 [3.42, 127.0.0.1:61544]
[2023-01-10 19:14:32,184] [runserver.py:147] [runserver:log_action] [INFO]- HTTP POST /cases/ 200 [3.40, 127.0.0.1:61548]
[2023-01-10 19:14:33,982] [runserver.py:147] [runserver:log_action] [INFO]- HTTP POST /cases/ 200 [1.48, 127.0.0.1:61565]
[2023-01-10 19:14:34,582] [runserver.py:147] [runserver:log_action] [INFO]- HTTP POST /cases/ 200 [2.09, 127.0.0.1:61564]
[2023-01-10 19:14:34,644] [runserver.py:147] [runserver:log_action] [INFO]- HTTP POST /cases/ 200 [2.15, 127.0.0.1:61563]
[2023-01-10 19:14:36,134] [log.py:241] [log:log_response] [ERROR]- Internal Server Error: /cases/
Traceback (most recent call last):
  File "D:\pythonList\web_python310\lib\site-packages\django\db\backends\utils.py", line 89, in _execute
    return self.cursor.execute(sql, params)
  File "D:\pythonList\web_python310\lib\site-packages\django\db\backends\mysql\base.py", line 75, in execute
    return self.cursor.execute(query, args)
  File "D:\pythonList\web_python310\lib\site-packages\pymysql\cursors.py", line 148, in execute
    result = self._query(query)
  File "D:\pythonList\web_python310\lib\site-packages\pymysql\cursors.py", line 310, in _query
    conn.query(q)
  File "D:\pythonList\web_python310\lib\site-packages\pymysql\connections.py", line 548, in query
    self._affected_rows = self._read_query_result(unbuffered=unbuffered)
  File "D:\pythonList\web_python310\lib\site-packages\pymysql\connections.py", line 775, in _read_query_result
    result.read()
  File "D:\pythonList\web_python310\lib\site-packages\pymysql\connections.py", line 1156, in read
    first_packet = self.connection._read_packet()
  File "D:\pythonList\web_python310\lib\site-packages\pymysql\connections.py", line 725, in _read_packet
    packet.raise_for_error()
  File "D:\pythonList\web_python310\lib\site-packages\pymysql\protocol.py", line 221, in raise_for_error
    err.raise_mysql_exception(self._data)
  File "D:\pythonList\web_python310\lib\site-packages\pymysql\err.py", line 143, in raise_mysql_exception
    raise errorclass(errno, errval)
pymysql.err.DataError: (1366, 'Incorrect string value: \'\\xF0\\x9F\\x98\\x85",...\' for column \'unchange\' at row 1')

The above exception was the direct cause of the following exception:

Traceback (most recent call last):
  File "D:\pythonList\web_python310\lib\site-packages\asgiref\sync.py", line 472, in thread_handler
    raise exc_info[1]
  File "D:\pythonList\web_python310\lib\site-packages\django\core\handlers\exception.py", line 42, in inner
    response = await get_response(request)
  File "D:\pythonList\web_python310\lib\site-packages\django\core\handlers\base.py", line 253, in _get_response_async
    response = await wrapped_callback(
  File "D:\pythonList\web_python310\lib\site-packages\asgiref\sync.py", line 435, in __call__
    ret = await asyncio.wait_for(future, timeout=None)
  File "D:\Python310\lib\asyncio\tasks.py", line 408, in wait_for
    return await fut
  File "D:\Python310\lib\concurrent\futures\thread.py", line 52, in run
    result = self.fn(*self.args, **self.kwargs)
  File "D:\pythonList\web_python310\lib\site-packages\asgiref\sync.py", line 476, in thread_handler
    return func(*args, **kwargs)
  File "D:\pythonList\web_python310\lib\site-packages\django\views\decorators\csrf.py", line 54, in wrapped_view
    return view_func(*args, **kwargs)
  File "D:\pythonList\web_python310\lib\site-packages\django\views\generic\base.py", line 103, in view
    return self.dispatch(request, *args, **kwargs)
  File "D:\pythonList\web_python310\lib\site-packages\rest_framework\views.py", line 509, in dispatch
    response = self.handle_exception(exc)
  File "D:\pythonList\web_python310\lib\site-packages\rest_framework\views.py", line 469, in handle_exception
    self.raise_uncaught_exception(exc)
  File "D:\pythonList\web_python310\lib\site-packages\rest_framework\views.py", line 480, in raise_uncaught_exception
    raise exc
  File "D:\pythonList\web_python310\lib\site-packages\rest_framework\views.py", line 506, in dispatch
    response = handler(request, *args, **kwargs)
  File "C:\Users\Administrator\Desktop\myweb\myweb\saas\views.py", line 440, in post
    serialize.save()
  File "D:\pythonList\web_python310\lib\site-packages\rest_framework\serializers.py", line 212, in save
    self.instance = self.create(validated_data)
  File "D:\pythonList\web_python310\lib\site-packages\rest_framework\serializers.py", line 962, in create
    instance = ModelClass._default_manager.create(**validated_data)
  File "D:\pythonList\web_python310\lib\site-packages\django\db\models\manager.py", line 85, in manager_method
    return getattr(self.get_queryset(), name)(*args, **kwargs)
  File "D:\pythonList\web_python310\lib\site-packages\django\db\models\query.py", line 671, in create
    obj.save(force_insert=True, using=self.db)
  File "D:\pythonList\web_python310\lib\site-packages\django\db\models\base.py", line 812, in save
    self.save_base(
  File "D:\pythonList\web_python310\lib\site-packages\django\db\models\base.py", line 863, in save_base
    updated = self._save_table(
  File "D:\pythonList\web_python310\lib\site-packages\django\db\models\base.py", line 1006, in _save_table
    results = self._do_insert(
  File "D:\pythonList\web_python310\lib\site-packages\django\db\models\base.py", line 1047, in _do_insert
    return manager._insert(
  File "D:\pythonList\web_python310\lib\site-packages\django\db\models\manager.py", line 85, in manager_method
    return getattr(self.get_queryset(), name)(*args, **kwargs)
  File "D:\pythonList\web_python310\lib\site-packages\django\db\models\query.py", line 1791, in _insert
    return query.get_compiler(using=using).execute_sql(returning_fields)
  File "D:\pythonList\web_python310\lib\site-packages\django\db\models\sql\compiler.py", line 1660, in execute_sql
    cursor.execute(sql, params)
  File "D:\pythonList\web_python310\lib\site-packages\django\db\backends\utils.py", line 103, in execute
    return super().execute(sql, params)
  File "D:\pythonList\web_python310\lib\site-packages\django\db\backends\utils.py", line 67, in execute
    return self._execute_with_wrappers(
  File "D:\pythonList\web_python310\lib\site-packages\django\db\backends\utils.py", line 80, in _execute_with_wrappers
    return executor(sql, params, many, context)
  File "D:\pythonList\web_python310\lib\site-packages\django\db\backends\utils.py", line 84, in _execute
    with self.db.wrap_database_errors:
  File "D:\pythonList\web_python310\lib\site-packages\django\db\utils.py", line 91, in __exit__
    raise dj_exc_value.with_traceback(traceback) from exc_value
  File "D:\pythonList\web_python310\lib\site-packages\django\db\backends\utils.py", line 89, in _execute
    return self.cursor.execute(sql, params)
  File "D:\pythonList\web_python310\lib\site-packages\django\db\backends\mysql\base.py", line 75, in execute
    return self.cursor.execute(query, args)
  File "D:\pythonList\web_python310\lib\site-packages\pymysql\cursors.py", line 148, in execute
    result = self._query(query)
  File "D:\pythonList\web_python310\lib\site-packages\pymysql\cursors.py", line 310, in _query
    conn.query(q)
  File "D:\pythonList\web_python310\lib\site-packages\pymysql\connections.py", line 548, in query
    self._affected_rows = self._read_query_result(unbuffered=unbuffered)
  File "D:\pythonList\web_python310\lib\site-packages\pymysql\connections.py", line 775, in _read_query_result
    result.read()
  File "D:\pythonList\web_python310\lib\site-packages\pymysql\connections.py", line 1156, in read
    first_packet = self.connection._read_packet()
  File "D:\pythonList\web_python310\lib\site-packages\pymysql\connections.py", line 725, in _read_packet
    packet.raise_for_error()
  File "D:\pythonList\web_python310\lib\site-packages\pymysql\protocol.py", line 221, in raise_for_error
    err.raise_mysql_exception(self._data)
  File "D:\pythonList\web_python310\lib\site-packages\pymysql\err.py", line 143, in raise_mysql_exception
    raise errorclass(errno, errval)
django.db.utils.DataError: (1366, 'Incorrect string value: \'\\xF0\\x9F\\x98\\x85",...\' for column \'unchange\' at row 1')
[2023-01-10 19:14:36,180] [runserver.py:160] [runserver:log_action] [ERROR]- HTTP POST /cases/ 500 [3.63, 127.0.0.1:61570]
[2023-01-10 19:15:34,787] [fiddlerExe.py:37] [fiddlerExe:getDatas] [INFO]- True
[2023-01-10 19:15:34,800] [runserver.py:147] [runserver:log_action] [INFO]- HTTP POST /dealFiddlerOnly/ 200 [0.02, 127.0.0.1:61607]
[2023-01-10 19:15:39,540] [runserver.py:147] [runserver:log_action] [INFO]- HTTP POST /cases/ 200 [0.10, 127.0.0.1:61616]
[2023-01-10 19:15:50,648] [runserver.py:147] [runserver:log_action] [INFO]- HTTP GET /cases/ 200 [0.57, 127.0.0.1:61626]
[2023-01-10 19:15:53,582] [runserver.py:147] [runserver:log_action] [INFO]- HTTP GET /cases/ 200 [0.65, 127.0.0.1:61633]
[2023-01-10 19:15:56,867] [runserver.py:147] [runserver:log_action] [INFO]- HTTP GET /cases/?page=2 200 [0.28, 127.0.0.1:61640]
[2023-01-10 19:16:01,609] [runserver.py:147] [runserver:log_action] [INFO]- HTTP GET /cases/?size=500&page=1 200 [0.35, 127.0.0.1:61652]
[2023-01-10 19:16:01,782] [runserver.py:147] [runserver:log_action] [INFO]- HTTP GET /cases/?size=500 200 [0.56, 127.0.0.1:61649]
[2023-01-10 19:16:07,549] [runserver.py:147] [runserver:log_action] [INFO]- HTTP DELETE /cases/98 200 [1.03, 127.0.0.1:61665]
[2023-01-10 19:16:07,549] [runserver.py:147] [runserver:log_action] [INFO]- HTTP DELETE /cases/101 200 [0.77, 127.0.0.1:61674]
[2023-01-10 19:16:07,580] [runserver.py:147] [runserver:log_action] [INFO]- HTTP DELETE /cases/100 200 [0.80, 127.0.0.1:61673]
[2023-01-10 19:16:07,608] [runserver.py:147] [runserver:log_action] [INFO]- HTTP DELETE /cases/97 200 [1.09, 127.0.0.1:61664]
[2023-01-10 19:16:07,645] [runserver.py:147] [runserver:log_action] [INFO]- HTTP DELETE /cases/99 200 [0.89, 127.0.0.1:61669]
[2023-01-10 19:16:08,240] [runserver.py:147] [runserver:log_action] [INFO]- HTTP DELETE /cases/102 200 [1.43, 127.0.0.1:61676]
[2023-01-10 19:16:08,579] [runserver.py:147] [runserver:log_action] [INFO]- HTTP DELETE /cases/103 200 [0.70, 127.0.0.1:61686]
[2023-01-10 19:16:08,726] [runserver.py:147] [runserver:log_action] [INFO]- HTTP DELETE /cases/105 200 [0.81, 127.0.0.1:61691]
[2023-01-10 19:16:09,031] [runserver.py:147] [runserver:log_action] [INFO]- HTTP DELETE /cases/107 200 [1.07, 127.0.0.1:61698]
[2023-01-10 19:16:09,081] [runserver.py:147] [runserver:log_action] [INFO]- HTTP DELETE /cases/104 200 [1.17, 127.0.0.1:61690]
[2023-01-10 19:16:09,252] [runserver.py:147] [runserver:log_action] [INFO]- HTTP DELETE /cases/106 200 [1.32, 127.0.0.1:61695]
[2023-01-10 19:16:09,761] [runserver.py:147] [runserver:log_action] [INFO]- HTTP GET /cases/ 200 [0.17, 127.0.0.1:61718]
[2023-01-10 19:16:16,858] [runserver.py:147] [runserver:log_action] [INFO]- HTTP DELETE /cases/108 200 [0.21, 127.0.0.1:61737]
[2023-01-10 19:16:16,873] [runserver.py:147] [runserver:log_action] [INFO]- HTTP DELETE /cases/109 200 [0.22, 127.0.0.1:61738]
[2023-01-10 19:16:16,907] [runserver.py:147] [runserver:log_action] [INFO]- HTTP DELETE /cases/112 200 [0.24, 127.0.0.1:61744]
[2023-01-10 19:16:17,023] [runserver.py:147] [runserver:log_action] [INFO]- HTTP DELETE /cases/110 200 [0.36, 127.0.0.1:61739]
[2023-01-10 19:16:17,028] [runserver.py:147] [runserver:log_action] [INFO]- HTTP DELETE /cases/111 200 [0.36, 127.0.0.1:61743]
[2023-01-10 19:16:17,030] [runserver.py:147] [runserver:log_action] [INFO]- HTTP DELETE /cases/113 200 [0.36, 127.0.0.1:61745]
[2023-01-10 19:16:17,848] [runserver.py:147] [runserver:log_action] [INFO]- HTTP GET /cases/ 200 [0.05, 127.0.0.1:61766]
[2023-01-10 19:16:37,247] [runserver.py:147] [runserver:log_action] [INFO]- HTTP GET /deleteAuto/ 200 [0.08, 127.0.0.1:61788]
[2023-01-10 19:20:46,198] [fiddlerExe.py:37] [fiddlerExe:getDatas] [INFO]- True
[2023-01-10 19:20:46,214] [runserver.py:147] [runserver:log_action] [INFO]- HTTP POST /dealFiddler/ 200 [0.05, 127.0.0.1:62628]
[2023-01-10 19:21:23,237] [fiddlerExe.py:37] [fiddlerExe:getDatas] [INFO]- True
[2023-01-10 19:21:23,251] [runserver.py:147] [runserver:log_action] [INFO]- HTTP POST /dealFiddlerOnly/ 200 [0.02, 127.0.0.1:62681]
[2023-01-10 19:21:31,857] [runserver.py:147] [runserver:log_action] [INFO]- HTTP POST /cases/ 200 [0.51, 127.0.0.1:62704]
[2023-01-10 19:21:31,862] [runserver.py:147] [runserver:log_action] [INFO]- HTTP POST /cases/ 200 [0.52, 127.0.0.1:62703]
[2023-01-10 19:21:46,389] [fiddlerExe.py:37] [fiddlerExe:getDatas] [INFO]- True
[2023-01-10 19:21:46,460] [runserver.py:147] [runserver:log_action] [INFO]- HTTP POST /dealFiddlerNotSql/ 200 [0.08, 127.0.0.1:62727]
[2023-01-10 19:26:23,087] [autoreload.py:677] [autoreload:run_with_reloader] [INFO]- Watching for file changes with StatReloader
[2023-01-10 19:26:30,766] [server.py:111] [server:run] [INFO]- HTTP/2 support enabled
[2023-01-10 19:26:30,804] [server.py:122] [server:run] [INFO]- Configuring endpoint tcp:port=8000:interface=127.0.0.1
[2023-01-10 19:26:30,805] [server.py:153] [server:listen_success] [INFO]- Listening on TCP address 127.0.0.1:8000
[2023-01-10 19:28:20,583] [fiddlerExe.py:37] [fiddlerExe:getDatas] [INFO]- True
[2023-01-10 19:28:20,596] [runserver.py:147] [runserver:log_action] [INFO]- HTTP POST /dealFiddlerOnly/ 200 [0.18, 127.0.0.1:63420]
[2023-01-10 19:28:27,667] [fiddlerExe.py:37] [fiddlerExe:getDatas] [INFO]- True
[2023-01-10 19:28:27,871] [runserver.py:147] [runserver:log_action] [INFO]- HTTP POST /dealFiddlerNotSql/ 200 [0.21, 127.0.0.1:63427]
[2023-01-10 19:28:33,484] [fiddlerExe.py:37] [fiddlerExe:getDatas] [INFO]- True
[2023-01-10 19:28:33,496] [runserver.py:147] [runserver:log_action] [INFO]- HTTP POST /dealFiddler/ 200 [0.02, 127.0.0.1:63439]
[2023-01-10 19:28:40,562] [runserver.py:147] [runserver:log_action] [INFO]- HTTP POST /cases/ 200 [0.23, 127.0.0.1:63460]
[2023-01-10 19:28:40,623] [runserver.py:147] [runserver:log_action] [INFO]- HTTP POST /cases/ 200 [0.30, 127.0.0.1:63454]
[2023-01-10 19:28:40,686] [runserver.py:147] [runserver:log_action] [INFO]- HTTP POST /cases/ 200 [0.35, 127.0.0.1:63461]
[2023-01-10 19:28:40,864] [runserver.py:147] [runserver:log_action] [INFO]- HTTP POST /cases/ 200 [0.54, 127.0.0.1:63455]
[2023-01-10 19:28:40,867] [runserver.py:147] [runserver:log_action] [INFO]- HTTP POST /cases/ 200 [0.54, 127.0.0.1:63456]
[2023-01-10 19:28:40,883] [runserver.py:147] [runserver:log_action] [INFO]- HTTP POST /cases/ 200 [0.55, 127.0.0.1:63458]
[2023-01-10 19:28:41,245] [runserver.py:147] [runserver:log_action] [INFO]- HTTP POST /cases/ 200 [0.25, 127.0.0.1:63481]
[2023-01-10 19:28:41,256] [runserver.py:147] [runserver:log_action] [INFO]- HTTP POST /cases/ 200 [0.30, 127.0.0.1:63477]
[2023-01-10 19:28:41,341] [runserver.py:147] [runserver:log_action] [INFO]- HTTP POST /cases/ 200 [0.13, 127.0.0.1:63486]
[2023-01-10 19:28:41,383] [runserver.py:147] [runserver:log_action] [INFO]- HTTP POST /cases/ 200 [0.17, 127.0.0.1:63488]
[2023-01-10 19:28:41,412] [runserver.py:147] [runserver:log_action] [INFO]- HTTP POST /cases/ 200 [0.21, 127.0.0.1:63485]
[2023-01-10 19:28:41,661] [runserver.py:147] [runserver:log_action] [INFO]- HTTP POST /cases/ 200 [0.10, 127.0.0.1:63498]
[2023-01-10 19:28:41,802] [runserver.py:147] [runserver:log_action] [INFO]- HTTP POST /cases/ 200 [0.23, 127.0.0.1:63501]
[2023-01-10 19:28:41,818] [runserver.py:147] [runserver:log_action] [INFO]- HTTP POST /cases/ 200 [0.17, 127.0.0.1:63504]
[2023-01-10 19:28:41,967] [runserver.py:147] [runserver:log_action] [INFO]- HTTP POST /cases/ 200 [0.20, 127.0.0.1:63508]
[2023-01-10 19:28:42,054] [runserver.py:147] [runserver:log_action] [INFO]- HTTP POST /cases/ 200 [0.28, 127.0.0.1:63510]
[2023-01-10 19:28:42,118] [runserver.py:147] [runserver:log_action] [INFO]- HTTP POST /cases/ 200 [0.10, 127.0.0.1:63515]
[2023-01-10 19:28:42,505] [log.py:241] [log:log_response] [ERROR]- Internal Server Error: /cases/
Traceback (most recent call last):
  File "D:\pythonList\web_python310\lib\site-packages\django\db\backends\utils.py", line 89, in _execute
    return self.cursor.execute(sql, params)
  File "D:\pythonList\web_python310\lib\site-packages\django\db\backends\mysql\base.py", line 75, in execute
    return self.cursor.execute(query, args)
  File "D:\pythonList\web_python310\lib\site-packages\pymysql\cursors.py", line 148, in execute
    result = self._query(query)
  File "D:\pythonList\web_python310\lib\site-packages\pymysql\cursors.py", line 310, in _query
    conn.query(q)
  File "D:\pythonList\web_python310\lib\site-packages\pymysql\connections.py", line 548, in query
    self._affected_rows = self._read_query_result(unbuffered=unbuffered)
  File "D:\pythonList\web_python310\lib\site-packages\pymysql\connections.py", line 775, in _read_query_result
    result.read()
  File "D:\pythonList\web_python310\lib\site-packages\pymysql\connections.py", line 1156, in read
    first_packet = self.connection._read_packet()
  File "D:\pythonList\web_python310\lib\site-packages\pymysql\connections.py", line 725, in _read_packet
    packet.raise_for_error()
  File "D:\pythonList\web_python310\lib\site-packages\pymysql\protocol.py", line 221, in raise_for_error
    err.raise_mysql_exception(self._data)
  File "D:\pythonList\web_python310\lib\site-packages\pymysql\err.py", line 143, in raise_mysql_exception
    raise errorclass(errno, errval)
pymysql.err.DataError: (1366, 'Incorrect string value: \'\\xF0\\x9F\\xA4\\x97",...\' for column \'unchange\' at row 1')

The above exception was the direct cause of the following exception:

Traceback (most recent call last):
  File "D:\pythonList\web_python310\lib\site-packages\asgiref\sync.py", line 472, in thread_handler
    raise exc_info[1]
  File "D:\pythonList\web_python310\lib\site-packages\django\core\handlers\exception.py", line 42, in inner
    response = await get_response(request)
  File "D:\pythonList\web_python310\lib\site-packages\django\core\handlers\base.py", line 253, in _get_response_async
    response = await wrapped_callback(
  File "D:\pythonList\web_python310\lib\site-packages\asgiref\sync.py", line 435, in __call__
    ret = await asyncio.wait_for(future, timeout=None)
  File "D:\Python310\lib\asyncio\tasks.py", line 408, in wait_for
    return await fut
  File "D:\Python310\lib\concurrent\futures\thread.py", line 52, in run
    result = self.fn(*self.args, **self.kwargs)
  File "D:\pythonList\web_python310\lib\site-packages\asgiref\sync.py", line 476, in thread_handler
    return func(*args, **kwargs)
  File "D:\pythonList\web_python310\lib\site-packages\django\views\decorators\csrf.py", line 54, in wrapped_view
    return view_func(*args, **kwargs)
  File "D:\pythonList\web_python310\lib\site-packages\django\views\generic\base.py", line 103, in view
    return self.dispatch(request, *args, **kwargs)
  File "D:\pythonList\web_python310\lib\site-packages\rest_framework\views.py", line 509, in dispatch
    response = self.handle_exception(exc)
  File "D:\pythonList\web_python310\lib\site-packages\rest_framework\views.py", line 469, in handle_exception
    self.raise_uncaught_exception(exc)
  File "D:\pythonList\web_python310\lib\site-packages\rest_framework\views.py", line 480, in raise_uncaught_exception
    raise exc
  File "D:\pythonList\web_python310\lib\site-packages\rest_framework\views.py", line 506, in dispatch
    response = handler(request, *args, **kwargs)
  File "C:\Users\Administrator\Desktop\myweb\myweb\saas\views.py", line 440, in post
    serialize.save()
  File "D:\pythonList\web_python310\lib\site-packages\rest_framework\serializers.py", line 212, in save
    self.instance = self.create(validated_data)
  File "D:\pythonList\web_python310\lib\site-packages\rest_framework\serializers.py", line 962, in create
    instance = ModelClass._default_manager.create(**validated_data)
  File "D:\pythonList\web_python310\lib\site-packages\django\db\models\manager.py", line 85, in manager_method
    return getattr(self.get_queryset(), name)(*args, **kwargs)
  File "D:\pythonList\web_python310\lib\site-packages\django\db\models\query.py", line 671, in create
    obj.save(force_insert=True, using=self.db)
  File "D:\pythonList\web_python310\lib\site-packages\django\db\models\base.py", line 812, in save
    self.save_base(
  File "D:\pythonList\web_python310\lib\site-packages\django\db\models\base.py", line 863, in save_base
    updated = self._save_table(
  File "D:\pythonList\web_python310\lib\site-packages\django\db\models\base.py", line 1006, in _save_table
    results = self._do_insert(
  File "D:\pythonList\web_python310\lib\site-packages\django\db\models\base.py", line 1047, in _do_insert
    return manager._insert(
  File "D:\pythonList\web_python310\lib\site-packages\django\db\models\manager.py", line 85, in manager_method
    return getattr(self.get_queryset(), name)(*args, **kwargs)
  File "D:\pythonList\web_python310\lib\site-packages\django\db\models\query.py", line 1791, in _insert
    return query.get_compiler(using=using).execute_sql(returning_fields)
  File "D:\pythonList\web_python310\lib\site-packages\django\db\models\sql\compiler.py", line 1660, in execute_sql
    cursor.execute(sql, params)
  File "D:\pythonList\web_python310\lib\site-packages\django\db\backends\utils.py", line 103, in execute
    return super().execute(sql, params)
  File "D:\pythonList\web_python310\lib\site-packages\django\db\backends\utils.py", line 67, in execute
    return self._execute_with_wrappers(
  File "D:\pythonList\web_python310\lib\site-packages\django\db\backends\utils.py", line 80, in _execute_with_wrappers
    return executor(sql, params, many, context)
  File "D:\pythonList\web_python310\lib\site-packages\django\db\backends\utils.py", line 84, in _execute
    with self.db.wrap_database_errors:
  File "D:\pythonList\web_python310\lib\site-packages\django\db\utils.py", line 91, in __exit__
    raise dj_exc_value.with_traceback(traceback) from exc_value
  File "D:\pythonList\web_python310\lib\site-packages\django\db\backends\utils.py", line 89, in _execute
    return self.cursor.execute(sql, params)
  File "D:\pythonList\web_python310\lib\site-packages\django\db\backends\mysql\base.py", line 75, in execute
    return self.cursor.execute(query, args)
  File "D:\pythonList\web_python310\lib\site-packages\pymysql\cursors.py", line 148, in execute
    result = self._query(query)
  File "D:\pythonList\web_python310\lib\site-packages\pymysql\cursors.py", line 310, in _query
    conn.query(q)
  File "D:\pythonList\web_python310\lib\site-packages\pymysql\connections.py", line 548, in query
    self._affected_rows = self._read_query_result(unbuffered=unbuffered)
  File "D:\pythonList\web_python310\lib\site-packages\pymysql\connections.py", line 775, in _read_query_result
    result.read()
  File "D:\pythonList\web_python310\lib\site-packages\pymysql\connections.py", line 1156, in read
    first_packet = self.connection._read_packet()
  File "D:\pythonList\web_python310\lib\site-packages\pymysql\connections.py", line 725, in _read_packet
    packet.raise_for_error()
  File "D:\pythonList\web_python310\lib\site-packages\pymysql\protocol.py", line 221, in raise_for_error
    err.raise_mysql_exception(self._data)
  File "D:\pythonList\web_python310\lib\site-packages\pymysql\err.py", line 143, in raise_mysql_exception
    raise errorclass(errno, errval)
django.db.utils.DataError: (1366, 'Incorrect string value: \'\\xF0\\x9F\\xA4\\x97",...\' for column \'unchange\' at row 1')
[2023-01-10 19:28:42,527] [runserver.py:160] [runserver:log_action] [ERROR]- HTTP POST /cases/ 500 [1.65, 127.0.0.1:63474]
[2023-01-10 19:28:52,052] [runserver.py:147] [runserver:log_action] [INFO]- HTTP GET /cases/ 200 [0.06, 127.0.0.1:63527]
[2023-01-10 19:28:57,778] [runserver.py:147] [runserver:log_action] [INFO]- HTTP GET /cases/ 200 [0.29, 127.0.0.1:63547]
[2023-01-10 19:29:02,508] [runserver.py:147] [runserver:log_action] [INFO]- HTTP GET /cases/?page=2 200 [0.36, 127.0.0.1:63558]
[2023-01-10 19:29:08,055] [runserver.py:147] [runserver:log_action] [INFO]- HTTP GET /cases/?page=1 200 [0.40, 127.0.0.1:63565]
[2023-01-10 19:29:09,852] [runserver.py:147] [runserver:log_action] [INFO]- HTTP GET /cases/?page=2 200 [0.08, 127.0.0.1:63571]
[2023-01-10 19:29:15,744] [runserver.py:147] [runserver:log_action] [INFO]- HTTP GET /cases/?size=500 200 [0.27, 127.0.0.1:63582]
[2023-01-10 19:29:15,753] [runserver.py:147] [runserver:log_action] [INFO]- HTTP GET /cases/?size=500&page=1 200 [0.22, 127.0.0.1:63585]
[2023-01-10 19:29:22,800] [runserver.py:147] [runserver:log_action] [INFO]- HTTP DELETE /cases/119 200 [0.73, 127.0.0.1:63607]
[2023-01-10 19:29:22,805] [runserver.py:147] [runserver:log_action] [INFO]- HTTP DELETE /cases/115 200 [0.75, 127.0.0.1:63602]
[2023-01-10 19:29:22,812] [runserver.py:147] [runserver:log_action] [INFO]- HTTP DELETE /cases/116 200 [0.76, 127.0.0.1:63603]
[2023-01-10 19:29:22,864] [runserver.py:147] [runserver:log_action] [INFO]- HTTP DELETE /cases/117 200 [0.81, 127.0.0.1:63604]
[2023-01-10 19:29:22,877] [runserver.py:147] [runserver:log_action] [INFO]- HTTP DELETE /cases/118 200 [0.82, 127.0.0.1:63605]
[2023-01-10 19:29:22,902] [runserver.py:147] [runserver:log_action] [INFO]- HTTP DELETE /cases/114 200 [0.85, 127.0.0.1:63601]
[2023-01-10 19:29:23,356] [runserver.py:147] [runserver:log_action] [INFO]- HTTP DELETE /cases/121 200 [0.21, 127.0.0.1:63624]
[2023-01-10 19:29:23,359] [runserver.py:147] [runserver:log_action] [INFO]- HTTP DELETE /cases/122 200 [0.21, 127.0.0.1:63625]
[2023-01-10 19:29:23,360] [runserver.py:147] [runserver:log_action] [INFO]- HTTP DELETE /cases/120 200 [0.22, 127.0.0.1:63623]
[2023-01-10 19:29:24,882] [runserver.py:147] [runserver:log_action] [INFO]- HTTP GET /cases/ 200 [0.52, 127.0.0.1:63643]
[2023-01-10 19:29:33,097] [runserver.py:147] [runserver:log_action] [INFO]- HTTP DELETE /cases/126 200 [0.47, 127.0.0.1:63665]
[2023-01-10 19:29:33,124] [runserver.py:147] [runserver:log_action] [INFO]- HTTP DELETE /cases/128 200 [0.48, 127.0.0.1:63669]
[2023-01-10 19:29:33,140] [runserver.py:147] [runserver:log_action] [INFO]- HTTP DELETE /cases/127 200 [0.51, 127.0.0.1:63668]
[2023-01-10 19:29:33,148] [runserver.py:147] [runserver:log_action] [INFO]- HTTP DELETE /cases/123 200 [0.53, 127.0.0.1:63660]
[2023-01-10 19:29:33,160] [runserver.py:147] [runserver:log_action] [INFO]- HTTP DELETE /cases/124 200 [0.54, 127.0.0.1:63663]
[2023-01-10 19:29:33,164] [runserver.py:147] [runserver:log_action] [INFO]- HTTP DELETE /cases/125 200 [0.54, 127.0.0.1:63664]
[2023-01-10 19:29:33,745] [runserver.py:147] [runserver:log_action] [INFO]- HTTP DELETE /cases/129 200 [0.33, 127.0.0.1:63682]
[2023-01-10 19:29:34,381] [runserver.py:147] [runserver:log_action] [INFO]- HTTP GET /cases/ 200 [0.16, 127.0.0.1:63698]
[2023-01-10 19:29:39,313] [runserver.py:147] [runserver:log_action] [INFO]- HTTP DELETE /cases/131 200 [0.09, 127.0.0.1:63715]
[2023-01-10 19:29:39,318] [runserver.py:147] [runserver:log_action] [INFO]- HTTP DELETE /cases/132 200 [0.09, 127.0.0.1:63716]
[2023-01-10 19:29:39,349] [runserver.py:147] [runserver:log_action] [INFO]- HTTP DELETE /cases/130 200 [0.13, 127.0.0.1:63714]
[2023-01-10 19:29:39,862] [runserver.py:147] [runserver:log_action] [INFO]- HTTP GET /cases/ 200 [0.03, 127.0.0.1:63730]
[2023-01-10 19:29:47,984] [fiddlerExe.py:37] [fiddlerExe:getDatas] [INFO]- True
[2023-01-10 19:29:47,994] [runserver.py:147] [runserver:log_action] [INFO]- HTTP POST /dealFiddlerOnly/ 200 [0.14, 127.0.0.1:63743]
[2023-01-10 19:29:52,037] [fiddlerExe.py:37] [fiddlerExe:getDatas] [INFO]- True
[2023-01-10 19:29:52,047] [runserver.py:147] [runserver:log_action] [INFO]- HTTP POST /dealFiddler/ 200 [0.02, 127.0.0.1:63748]
[2023-01-10 19:29:58,083] [runserver.py:147] [runserver:log_action] [INFO]- HTTP POST /cases/ 200 [0.14, 127.0.0.1:63770]
[2023-01-10 19:29:58,121] [runserver.py:147] [runserver:log_action] [INFO]- HTTP POST /cases/ 200 [0.18, 127.0.0.1:63766]
[2023-01-10 19:29:58,124] [runserver.py:147] [runserver:log_action] [INFO]- HTTP POST /cases/ 200 [0.19, 127.0.0.1:63768]
[2023-01-10 19:29:58,192] [runserver.py:147] [runserver:log_action] [INFO]- HTTP POST /cases/ 200 [0.25, 127.0.0.1:63767]
[2023-01-10 19:29:58,207] [runserver.py:147] [runserver:log_action] [INFO]- HTTP POST /cases/ 200 [0.26, 127.0.0.1:63771]
[2023-01-10 19:29:58,214] [runserver.py:147] [runserver:log_action] [INFO]- HTTP POST /cases/ 200 [0.27, 127.0.0.1:63769]
[2023-01-10 19:29:58,622] [runserver.py:147] [runserver:log_action] [INFO]- HTTP POST /cases/ 200 [0.15, 127.0.0.1:63789]
[2023-01-10 19:29:58,739] [runserver.py:147] [runserver:log_action] [INFO]- HTTP POST /cases/ 200 [0.21, 127.0.0.1:63797]
[2023-01-10 19:29:58,740] [runserver.py:147] [runserver:log_action] [INFO]- HTTP POST /cases/ 200 [0.26, 127.0.0.1:63790]
[2023-01-10 19:29:58,742] [runserver.py:147] [runserver:log_action] [INFO]- HTTP POST /cases/ 200 [0.23, 127.0.0.1:63793]
[2023-01-10 19:29:58,758] [runserver.py:147] [runserver:log_action] [INFO]- HTTP POST /cases/ 200 [0.21, 127.0.0.1:63798]
[2023-01-10 19:29:59,124] [runserver.py:147] [runserver:log_action] [INFO]- HTTP POST /cases/ 200 [0.19, 127.0.0.1:63808]
[2023-01-10 19:29:59,299] [runserver.py:147] [runserver:log_action] [INFO]- HTTP POST /cases/ 200 [0.23, 127.0.0.1:63814]
[2023-01-10 19:29:59,302] [runserver.py:147] [runserver:log_action] [INFO]- HTTP POST /cases/ 200 [0.23, 127.0.0.1:63816]
[2023-01-10 19:29:59,348] [runserver.py:147] [runserver:log_action] [INFO]- HTTP POST /cases/ 200 [0.21, 127.0.0.1:63822]
[2023-01-10 19:29:59,353] [runserver.py:147] [runserver:log_action] [INFO]- HTTP POST /cases/ 200 [0.28, 127.0.0.1:63815]
[2023-01-10 19:29:59,626] [log.py:241] [log:log_response] [ERROR]- Internal Server Error: /cases/
Traceback (most recent call last):
  File "D:\pythonList\web_python310\lib\site-packages\django\db\backends\utils.py", line 89, in _execute
    return self.cursor.execute(sql, params)
  File "D:\pythonList\web_python310\lib\site-packages\django\db\backends\mysql\base.py", line 75, in execute
    return self.cursor.execute(query, args)
  File "D:\pythonList\web_python310\lib\site-packages\pymysql\cursors.py", line 148, in execute
    result = self._query(query)
  File "D:\pythonList\web_python310\lib\site-packages\pymysql\cursors.py", line 310, in _query
    conn.query(q)
  File "D:\pythonList\web_python310\lib\site-packages\pymysql\connections.py", line 548, in query
    self._affected_rows = self._read_query_result(unbuffered=unbuffered)
  File "D:\pythonList\web_python310\lib\site-packages\pymysql\connections.py", line 775, in _read_query_result
    result.read()
  File "D:\pythonList\web_python310\lib\site-packages\pymysql\connections.py", line 1156, in read
    first_packet = self.connection._read_packet()
  File "D:\pythonList\web_python310\lib\site-packages\pymysql\connections.py", line 725, in _read_packet
    packet.raise_for_error()
  File "D:\pythonList\web_python310\lib\site-packages\pymysql\protocol.py", line 221, in raise_for_error
    err.raise_mysql_exception(self._data)
  File "D:\pythonList\web_python310\lib\site-packages\pymysql\err.py", line 143, in raise_mysql_exception
    raise errorclass(errno, errval)
pymysql.err.DataError: (1366, 'Incorrect string value: \'\\xF0\\x9F\\xA4\\x97",...\' for column \'unchange\' at row 1')

The above exception was the direct cause of the following exception:

Traceback (most recent call last):
  File "D:\pythonList\web_python310\lib\site-packages\asgiref\sync.py", line 472, in thread_handler
    raise exc_info[1]
  File "D:\pythonList\web_python310\lib\site-packages\django\core\handlers\exception.py", line 42, in inner
    response = await get_response(request)
  File "D:\pythonList\web_python310\lib\site-packages\django\core\handlers\base.py", line 253, in _get_response_async
    response = await wrapped_callback(
  File "D:\pythonList\web_python310\lib\site-packages\asgiref\sync.py", line 435, in __call__
    ret = await asyncio.wait_for(future, timeout=None)
  File "D:\Python310\lib\asyncio\tasks.py", line 408, in wait_for
    return await fut
  File "D:\Python310\lib\concurrent\futures\thread.py", line 52, in run
    result = self.fn(*self.args, **self.kwargs)
  File "D:\pythonList\web_python310\lib\site-packages\asgiref\sync.py", line 476, in thread_handler
    return func(*args, **kwargs)
  File "D:\pythonList\web_python310\lib\site-packages\django\views\decorators\csrf.py", line 54, in wrapped_view
    return view_func(*args, **kwargs)
  File "D:\pythonList\web_python310\lib\site-packages\django\views\generic\base.py", line 103, in view
    return self.dispatch(request, *args, **kwargs)
  File "D:\pythonList\web_python310\lib\site-packages\rest_framework\views.py", line 509, in dispatch
    response = self.handle_exception(exc)
  File "D:\pythonList\web_python310\lib\site-packages\rest_framework\views.py", line 469, in handle_exception
    self.raise_uncaught_exception(exc)
  File "D:\pythonList\web_python310\lib\site-packages\rest_framework\views.py", line 480, in raise_uncaught_exception
    raise exc
  File "D:\pythonList\web_python310\lib\site-packages\rest_framework\views.py", line 506, in dispatch
    response = handler(request, *args, **kwargs)
  File "C:\Users\Administrator\Desktop\myweb\myweb\saas\views.py", line 440, in post
    serialize.save()
  File "D:\pythonList\web_python310\lib\site-packages\rest_framework\serializers.py", line 212, in save
    self.instance = self.create(validated_data)
  File "D:\pythonList\web_python310\lib\site-packages\rest_framework\serializers.py", line 962, in create
    instance = ModelClass._default_manager.create(**validated_data)
  File "D:\pythonList\web_python310\lib\site-packages\django\db\models\manager.py", line 85, in manager_method
    return getattr(self.get_queryset(), name)(*args, **kwargs)
  File "D:\pythonList\web_python310\lib\site-packages\django\db\models\query.py", line 671, in create
    obj.save(force_insert=True, using=self.db)
  File "D:\pythonList\web_python310\lib\site-packages\django\db\models\base.py", line 812, in save
    self.save_base(
  File "D:\pythonList\web_python310\lib\site-packages\django\db\models\base.py", line 863, in save_base
    updated = self._save_table(
  File "D:\pythonList\web_python310\lib\site-packages\django\db\models\base.py", line 1006, in _save_table
    results = self._do_insert(
  File "D:\pythonList\web_python310\lib\site-packages\django\db\models\base.py", line 1047, in _do_insert
    return manager._insert(
  File "D:\pythonList\web_python310\lib\site-packages\django\db\models\manager.py", line 85, in manager_method
    return getattr(self.get_queryset(), name)(*args, **kwargs)
  File "D:\pythonList\web_python310\lib\site-packages\django\db\models\query.py", line 1791, in _insert
    return query.get_compiler(using=using).execute_sql(returning_fields)
  File "D:\pythonList\web_python310\lib\site-packages\django\db\models\sql\compiler.py", line 1660, in execute_sql
    cursor.execute(sql, params)
  File "D:\pythonList\web_python310\lib\site-packages\django\db\backends\utils.py", line 103, in execute
    return super().execute(sql, params)
  File "D:\pythonList\web_python310\lib\site-packages\django\db\backends\utils.py", line 67, in execute
    return self._execute_with_wrappers(
  File "D:\pythonList\web_python310\lib\site-packages\django\db\backends\utils.py", line 80, in _execute_with_wrappers
    return executor(sql, params, many, context)
  File "D:\pythonList\web_python310\lib\site-packages\django\db\backends\utils.py", line 84, in _execute
    with self.db.wrap_database_errors:
  File "D:\pythonList\web_python310\lib\site-packages\django\db\utils.py", line 91, in __exit__
    raise dj_exc_value.with_traceback(traceback) from exc_value
  File "D:\pythonList\web_python310\lib\site-packages\django\db\backends\utils.py", line 89, in _execute
    return self.cursor.execute(sql, params)
  File "D:\pythonList\web_python310\lib\site-packages\django\db\backends\mysql\base.py", line 75, in execute
    return self.cursor.execute(query, args)
  File "D:\pythonList\web_python310\lib\site-packages\pymysql\cursors.py", line 148, in execute
    result = self._query(query)
  File "D:\pythonList\web_python310\lib\site-packages\pymysql\cursors.py", line 310, in _query
    conn.query(q)
  File "D:\pythonList\web_python310\lib\site-packages\pymysql\connections.py", line 548, in query
    self._affected_rows = self._read_query_result(unbuffered=unbuffered)
  File "D:\pythonList\web_python310\lib\site-packages\pymysql\connections.py", line 775, in _read_query_result
    result.read()
  File "D:\pythonList\web_python310\lib\site-packages\pymysql\connections.py", line 1156, in read
    first_packet = self.connection._read_packet()
  File "D:\pythonList\web_python310\lib\site-packages\pymysql\connections.py", line 725, in _read_packet
    packet.raise_for_error()
  File "D:\pythonList\web_python310\lib\site-packages\pymysql\protocol.py", line 221, in raise_for_error
    err.raise_mysql_exception(self._data)
  File "D:\pythonList\web_python310\lib\site-packages\pymysql\err.py", line 143, in raise_mysql_exception
    raise errorclass(errno, errval)
django.db.utils.DataError: (1366, 'Incorrect string value: \'\\xF0\\x9F\\xA4\\x97",...\' for column \'unchange\' at row 1')
[2023-01-10 19:29:59,641] [runserver.py:147] [runserver:log_action] [INFO]- HTTP POST /cases/ 200 [0.19, 127.0.0.1:63825]
[2023-01-10 19:29:59,645] [runserver.py:160] [runserver:log_action] [ERROR]- HTTP POST /cases/ 500 [1.25, 127.0.0.1:63785]
[2023-01-10 19:30:03,150] [runserver.py:147] [runserver:log_action] [INFO]- HTTP GET /cases/ 200 [0.10, 127.0.0.1:63834]
[2023-01-10 19:30:04,503] [runserver.py:147] [runserver:log_action] [INFO]- HTTP GET /cases/ 200 [0.09, 127.0.0.1:63848]
[2023-01-10 19:30:07,511] [runserver.py:147] [runserver:log_action] [INFO]- HTTP GET /cases/?page=2 200 [0.07, 127.0.0.1:63858]
[2023-01-10 19:30:11,774] [runserver.py:147] [runserver:log_action] [INFO]- HTTP GET /cases/?page=1 200 [0.09, 127.0.0.1:63863]
[2023-01-10 19:30:14,416] [runserver.py:147] [runserver:log_action] [INFO]- HTTP GET /cases/?page=2 200 [0.04, 127.0.0.1:63869]
[2023-01-10 19:31:25,146] [runserver.py:147] [runserver:log_action] [INFO]- HTTP GET /cases/?search=%2Fshakespeare%2Fnotes%2F105755497%2Fcomments 200 [0.43, 127.0.0.1:63905]
[2023-01-10 19:31:57,092] [log.py:241] [log:log_response] [ERROR]- Internal Server Error: /cases/
Traceback (most recent call last):
  File "D:\pythonList\web_python310\lib\site-packages\django\db\backends\utils.py", line 89, in _execute
    return self.cursor.execute(sql, params)
  File "D:\pythonList\web_python310\lib\site-packages\django\db\backends\mysql\base.py", line 75, in execute
    return self.cursor.execute(query, args)
  File "D:\pythonList\web_python310\lib\site-packages\pymysql\cursors.py", line 148, in execute
    result = self._query(query)
  File "D:\pythonList\web_python310\lib\site-packages\pymysql\cursors.py", line 310, in _query
    conn.query(q)
  File "D:\pythonList\web_python310\lib\site-packages\pymysql\connections.py", line 548, in query
    self._affected_rows = self._read_query_result(unbuffered=unbuffered)
  File "D:\pythonList\web_python310\lib\site-packages\pymysql\connections.py", line 775, in _read_query_result
    result.read()
  File "D:\pythonList\web_python310\lib\site-packages\pymysql\connections.py", line 1156, in read
    first_packet = self.connection._read_packet()
  File "D:\pythonList\web_python310\lib\site-packages\pymysql\connections.py", line 725, in _read_packet
    packet.raise_for_error()
  File "D:\pythonList\web_python310\lib\site-packages\pymysql\protocol.py", line 221, in raise_for_error
    err.raise_mysql_exception(self._data)
  File "D:\pythonList\web_python310\lib\site-packages\pymysql\err.py", line 143, in raise_mysql_exception
    raise errorclass(errno, errval)
pymysql.err.DataError: (1366, 'Incorrect string value: \'\\xF0\\x9F\\xA4\\x97",...\' for column \'unchange\' at row 1')

The above exception was the direct cause of the following exception:

Traceback (most recent call last):
  File "D:\pythonList\web_python310\lib\site-packages\asgiref\sync.py", line 472, in thread_handler
    raise exc_info[1]
  File "D:\pythonList\web_python310\lib\site-packages\django\core\handlers\exception.py", line 42, in inner
    response = await get_response(request)
  File "D:\pythonList\web_python310\lib\site-packages\django\core\handlers\base.py", line 253, in _get_response_async
    response = await wrapped_callback(
  File "D:\pythonList\web_python310\lib\site-packages\asgiref\sync.py", line 435, in __call__
    ret = await asyncio.wait_for(future, timeout=None)
  File "D:\Python310\lib\asyncio\tasks.py", line 408, in wait_for
    return await fut
  File "D:\Python310\lib\concurrent\futures\thread.py", line 52, in run
    result = self.fn(*self.args, **self.kwargs)
  File "D:\pythonList\web_python310\lib\site-packages\asgiref\sync.py", line 476, in thread_handler
    return func(*args, **kwargs)
  File "D:\pythonList\web_python310\lib\site-packages\django\views\decorators\csrf.py", line 54, in wrapped_view
    return view_func(*args, **kwargs)
  File "D:\pythonList\web_python310\lib\site-packages\django\views\generic\base.py", line 103, in view
    return self.dispatch(request, *args, **kwargs)
  File "D:\pythonList\web_python310\lib\site-packages\rest_framework\views.py", line 509, in dispatch
    response = self.handle_exception(exc)
  File "D:\pythonList\web_python310\lib\site-packages\rest_framework\views.py", line 469, in handle_exception
    self.raise_uncaught_exception(exc)
  File "D:\pythonList\web_python310\lib\site-packages\rest_framework\views.py", line 480, in raise_uncaught_exception
    raise exc
  File "D:\pythonList\web_python310\lib\site-packages\rest_framework\views.py", line 506, in dispatch
    response = handler(request, *args, **kwargs)
  File "C:\Users\Administrator\Desktop\myweb\myweb\saas\views.py", line 440, in post
    serialize.save()
  File "D:\pythonList\web_python310\lib\site-packages\rest_framework\serializers.py", line 212, in save
    self.instance = self.create(validated_data)
  File "D:\pythonList\web_python310\lib\site-packages\rest_framework\serializers.py", line 962, in create
    instance = ModelClass._default_manager.create(**validated_data)
  File "D:\pythonList\web_python310\lib\site-packages\django\db\models\manager.py", line 85, in manager_method
    return getattr(self.get_queryset(), name)(*args, **kwargs)
  File "D:\pythonList\web_python310\lib\site-packages\django\db\models\query.py", line 671, in create
    obj.save(force_insert=True, using=self.db)
  File "D:\pythonList\web_python310\lib\site-packages\django\db\models\base.py", line 812, in save
    self.save_base(
  File "D:\pythonList\web_python310\lib\site-packages\django\db\models\base.py", line 863, in save_base
    updated = self._save_table(
  File "D:\pythonList\web_python310\lib\site-packages\django\db\models\base.py", line 1006, in _save_table
    results = self._do_insert(
  File "D:\pythonList\web_python310\lib\site-packages\django\db\models\base.py", line 1047, in _do_insert
    return manager._insert(
  File "D:\pythonList\web_python310\lib\site-packages\django\db\models\manager.py", line 85, in manager_method
    return getattr(self.get_queryset(), name)(*args, **kwargs)
  File "D:\pythonList\web_python310\lib\site-packages\django\db\models\query.py", line 1791, in _insert
    return query.get_compiler(using=using).execute_sql(returning_fields)
  File "D:\pythonList\web_python310\lib\site-packages\django\db\models\sql\compiler.py", line 1660, in execute_sql
    cursor.execute(sql, params)
  File "D:\pythonList\web_python310\lib\site-packages\django\db\backends\utils.py", line 103, in execute
    return super().execute(sql, params)
  File "D:\pythonList\web_python310\lib\site-packages\django\db\backends\utils.py", line 67, in execute
    return self._execute_with_wrappers(
  File "D:\pythonList\web_python310\lib\site-packages\django\db\backends\utils.py", line 80, in _execute_with_wrappers
    return executor(sql, params, many, context)
  File "D:\pythonList\web_python310\lib\site-packages\django\db\backends\utils.py", line 84, in _execute
    with self.db.wrap_database_errors:
  File "D:\pythonList\web_python310\lib\site-packages\django\db\utils.py", line 91, in __exit__
    raise dj_exc_value.with_traceback(traceback) from exc_value
  File "D:\pythonList\web_python310\lib\site-packages\django\db\backends\utils.py", line 89, in _execute
    return self.cursor.execute(sql, params)
  File "D:\pythonList\web_python310\lib\site-packages\django\db\backends\mysql\base.py", line 75, in execute
    return self.cursor.execute(query, args)
  File "D:\pythonList\web_python310\lib\site-packages\pymysql\cursors.py", line 148, in execute
    result = self._query(query)
  File "D:\pythonList\web_python310\lib\site-packages\pymysql\cursors.py", line 310, in _query
    conn.query(q)
  File "D:\pythonList\web_python310\lib\site-packages\pymysql\connections.py", line 548, in query
    self._affected_rows = self._read_query_result(unbuffered=unbuffered)
  File "D:\pythonList\web_python310\lib\site-packages\pymysql\connections.py", line 775, in _read_query_result
    result.read()
  File "D:\pythonList\web_python310\lib\site-packages\pymysql\connections.py", line 1156, in read
    first_packet = self.connection._read_packet()
  File "D:\pythonList\web_python310\lib\site-packages\pymysql\connections.py", line 725, in _read_packet
    packet.raise_for_error()
  File "D:\pythonList\web_python310\lib\site-packages\pymysql\protocol.py", line 221, in raise_for_error
    err.raise_mysql_exception(self._data)
  File "D:\pythonList\web_python310\lib\site-packages\pymysql\err.py", line 143, in raise_mysql_exception
    raise errorclass(errno, errval)
django.db.utils.DataError: (1366, 'Incorrect string value: \'\\xF0\\x9F\\xA4\\x97",...\' for column \'unchange\' at row 1')
[2023-01-10 19:31:57,107] [runserver.py:160] [runserver:log_action] [ERROR]- HTTP POST /cases/ 500 [0.30, 127.0.0.1:63925]
[2023-01-10 19:32:05,200] [runserver.py:147] [runserver:log_action] [INFO]- HTTP GET /cases/?search=%2Fshakespeare%2Fnotes%2F105755497%2Fcomments 200 [0.08, 127.0.0.1:63936]
[2023-01-10 19:32:06,134] [runserver.py:147] [runserver:log_action] [INFO]- HTTP GET /cases/?search=%2Fshakespeare%2Fnotes%2F105755497%2Fcomments 200 [0.13, 127.0.0.1:63939]
[2023-01-10 19:32:57,125] [runserver.py:147] [runserver:log_action] [INFO]- HTTP GET /cases/?search=%2Fshakespeare%2Fnotes%2F105755497%2Fcomments 200 [0.05, 127.0.0.1:63967]
[2023-01-10 19:32:59,894] [runserver.py:147] [runserver:log_action] [INFO]- HTTP GET /cases/?search= 200 [0.12, 127.0.0.1:63974]
[2023-01-10 19:33:59,034] [log.py:241] [log:log_response] [ERROR]- Internal Server Error: /cases/
Traceback (most recent call last):
  File "D:\pythonList\web_python310\lib\site-packages\django\db\backends\utils.py", line 89, in _execute
    return self.cursor.execute(sql, params)
  File "D:\pythonList\web_python310\lib\site-packages\django\db\backends\mysql\base.py", line 75, in execute
    return self.cursor.execute(query, args)
  File "D:\pythonList\web_python310\lib\site-packages\pymysql\cursors.py", line 148, in execute
    result = self._query(query)
  File "D:\pythonList\web_python310\lib\site-packages\pymysql\cursors.py", line 310, in _query
    conn.query(q)
  File "D:\pythonList\web_python310\lib\site-packages\pymysql\connections.py", line 548, in query
    self._affected_rows = self._read_query_result(unbuffered=unbuffered)
  File "D:\pythonList\web_python310\lib\site-packages\pymysql\connections.py", line 775, in _read_query_result
    result.read()
  File "D:\pythonList\web_python310\lib\site-packages\pymysql\connections.py", line 1156, in read
    first_packet = self.connection._read_packet()
  File "D:\pythonList\web_python310\lib\site-packages\pymysql\connections.py", line 725, in _read_packet
    packet.raise_for_error()
  File "D:\pythonList\web_python310\lib\site-packages\pymysql\protocol.py", line 221, in raise_for_error
    err.raise_mysql_exception(self._data)
  File "D:\pythonList\web_python310\lib\site-packages\pymysql\err.py", line 143, in raise_mysql_exception
    raise errorclass(errno, errval)
pymysql.err.DataError: (1366, 'Incorrect string value: \'\\xF0\\x9F\\xA4\\x97",...\' for column \'unchange\' at row 1')

The above exception was the direct cause of the following exception:

Traceback (most recent call last):
  File "D:\pythonList\web_python310\lib\site-packages\asgiref\sync.py", line 472, in thread_handler
    raise exc_info[1]
  File "D:\pythonList\web_python310\lib\site-packages\django\core\handlers\exception.py", line 42, in inner
    response = await get_response(request)
  File "D:\pythonList\web_python310\lib\site-packages\django\core\handlers\base.py", line 253, in _get_response_async
    response = await wrapped_callback(
  File "D:\pythonList\web_python310\lib\site-packages\asgiref\sync.py", line 435, in __call__
    ret = await asyncio.wait_for(future, timeout=None)
  File "D:\Python310\lib\asyncio\tasks.py", line 408, in wait_for
    return await fut
  File "D:\Python310\lib\concurrent\futures\thread.py", line 52, in run
    result = self.fn(*self.args, **self.kwargs)
  File "D:\pythonList\web_python310\lib\site-packages\asgiref\sync.py", line 476, in thread_handler
    return func(*args, **kwargs)
  File "D:\pythonList\web_python310\lib\site-packages\django\views\decorators\csrf.py", line 54, in wrapped_view
    return view_func(*args, **kwargs)
  File "D:\pythonList\web_python310\lib\site-packages\django\views\generic\base.py", line 103, in view
    return self.dispatch(request, *args, **kwargs)
  File "D:\pythonList\web_python310\lib\site-packages\rest_framework\views.py", line 509, in dispatch
    response = self.handle_exception(exc)
  File "D:\pythonList\web_python310\lib\site-packages\rest_framework\views.py", line 469, in handle_exception
    self.raise_uncaught_exception(exc)
  File "D:\pythonList\web_python310\lib\site-packages\rest_framework\views.py", line 480, in raise_uncaught_exception
    raise exc
  File "D:\pythonList\web_python310\lib\site-packages\rest_framework\views.py", line 506, in dispatch
    response = handler(request, *args, **kwargs)
  File "C:\Users\Administrator\Desktop\myweb\myweb\saas\views.py", line 440, in post
    serialize.save()
  File "D:\pythonList\web_python310\lib\site-packages\rest_framework\serializers.py", line 212, in save
    self.instance = self.create(validated_data)
  File "D:\pythonList\web_python310\lib\site-packages\rest_framework\serializers.py", line 962, in create
    instance = ModelClass._default_manager.create(**validated_data)
  File "D:\pythonList\web_python310\lib\site-packages\django\db\models\manager.py", line 85, in manager_method
    return getattr(self.get_queryset(), name)(*args, **kwargs)
  File "D:\pythonList\web_python310\lib\site-packages\django\db\models\query.py", line 671, in create
    obj.save(force_insert=True, using=self.db)
  File "D:\pythonList\web_python310\lib\site-packages\django\db\models\base.py", line 812, in save
    self.save_base(
  File "D:\pythonList\web_python310\lib\site-packages\django\db\models\base.py", line 863, in save_base
    updated = self._save_table(
  File "D:\pythonList\web_python310\lib\site-packages\django\db\models\base.py", line 1006, in _save_table
    results = self._do_insert(
  File "D:\pythonList\web_python310\lib\site-packages\django\db\models\base.py", line 1047, in _do_insert
    return manager._insert(
  File "D:\pythonList\web_python310\lib\site-packages\django\db\models\manager.py", line 85, in manager_method
    return getattr(self.get_queryset(), name)(*args, **kwargs)
  File "D:\pythonList\web_python310\lib\site-packages\django\db\models\query.py", line 1791, in _insert
    return query.get_compiler(using=using).execute_sql(returning_fields)
  File "D:\pythonList\web_python310\lib\site-packages\django\db\models\sql\compiler.py", line 1660, in execute_sql
    cursor.execute(sql, params)
  File "D:\pythonList\web_python310\lib\site-packages\django\db\backends\utils.py", line 103, in execute
    return super().execute(sql, params)
  File "D:\pythonList\web_python310\lib\site-packages\django\db\backends\utils.py", line 67, in execute
    return self._execute_with_wrappers(
  File "D:\pythonList\web_python310\lib\site-packages\django\db\backends\utils.py", line 80, in _execute_with_wrappers
    return executor(sql, params, many, context)
  File "D:\pythonList\web_python310\lib\site-packages\django\db\backends\utils.py", line 84, in _execute
    with self.db.wrap_database_errors:
  File "D:\pythonList\web_python310\lib\site-packages\django\db\utils.py", line 91, in __exit__
    raise dj_exc_value.with_traceback(traceback) from exc_value
  File "D:\pythonList\web_python310\lib\site-packages\django\db\backends\utils.py", line 89, in _execute
    return self.cursor.execute(sql, params)
  File "D:\pythonList\web_python310\lib\site-packages\django\db\backends\mysql\base.py", line 75, in execute
    return self.cursor.execute(query, args)
  File "D:\pythonList\web_python310\lib\site-packages\pymysql\cursors.py", line 148, in execute
    result = self._query(query)
  File "D:\pythonList\web_python310\lib\site-packages\pymysql\cursors.py", line 310, in _query
    conn.query(q)
  File "D:\pythonList\web_python310\lib\site-packages\pymysql\connections.py", line 548, in query
    self._affected_rows = self._read_query_result(unbuffered=unbuffered)
  File "D:\pythonList\web_python310\lib\site-packages\pymysql\connections.py", line 775, in _read_query_result
    result.read()
  File "D:\pythonList\web_python310\lib\site-packages\pymysql\connections.py", line 1156, in read
    first_packet = self.connection._read_packet()
  File "D:\pythonList\web_python310\lib\site-packages\pymysql\connections.py", line 725, in _read_packet
    packet.raise_for_error()
  File "D:\pythonList\web_python310\lib\site-packages\pymysql\protocol.py", line 221, in raise_for_error
    err.raise_mysql_exception(self._data)
  File "D:\pythonList\web_python310\lib\site-packages\pymysql\err.py", line 143, in raise_mysql_exception
    raise errorclass(errno, errval)
django.db.utils.DataError: (1366, 'Incorrect string value: \'\\xF0\\x9F\\xA4\\x97",...\' for column \'unchange\' at row 1')
[2023-01-10 19:33:59,049] [runserver.py:160] [runserver:log_action] [ERROR]- HTTP POST /cases/ 500 [0.30, 127.0.0.1:64006]
[2023-01-10 19:35:50,047] [log.py:241] [log:log_response] [ERROR]- Internal Server Error: /cases/
Traceback (most recent call last):
  File "D:\pythonList\web_python310\lib\site-packages\django\db\backends\utils.py", line 89, in _execute
    return self.cursor.execute(sql, params)
  File "D:\pythonList\web_python310\lib\site-packages\django\db\backends\mysql\base.py", line 75, in execute
    return self.cursor.execute(query, args)
  File "D:\pythonList\web_python310\lib\site-packages\pymysql\cursors.py", line 148, in execute
    result = self._query(query)
  File "D:\pythonList\web_python310\lib\site-packages\pymysql\cursors.py", line 310, in _query
    conn.query(q)
  File "D:\pythonList\web_python310\lib\site-packages\pymysql\connections.py", line 548, in query
    self._affected_rows = self._read_query_result(unbuffered=unbuffered)
  File "D:\pythonList\web_python310\lib\site-packages\pymysql\connections.py", line 775, in _read_query_result
    result.read()
  File "D:\pythonList\web_python310\lib\site-packages\pymysql\connections.py", line 1156, in read
    first_packet = self.connection._read_packet()
  File "D:\pythonList\web_python310\lib\site-packages\pymysql\connections.py", line 725, in _read_packet
    packet.raise_for_error()
  File "D:\pythonList\web_python310\lib\site-packages\pymysql\protocol.py", line 221, in raise_for_error
    err.raise_mysql_exception(self._data)
  File "D:\pythonList\web_python310\lib\site-packages\pymysql\err.py", line 143, in raise_mysql_exception
    raise errorclass(errno, errval)
pymysql.err.DataError: (1366, 'Incorrect string value: \'\\xF0\\x9F\\xA4\\x97",...\' for column \'unchange\' at row 1')

The above exception was the direct cause of the following exception:

Traceback (most recent call last):
  File "D:\pythonList\web_python310\lib\site-packages\asgiref\sync.py", line 472, in thread_handler
    raise exc_info[1]
  File "D:\pythonList\web_python310\lib\site-packages\django\core\handlers\exception.py", line 42, in inner
    response = await get_response(request)
  File "D:\pythonList\web_python310\lib\site-packages\django\core\handlers\base.py", line 253, in _get_response_async
    response = await wrapped_callback(
  File "D:\pythonList\web_python310\lib\site-packages\asgiref\sync.py", line 435, in __call__
    ret = await asyncio.wait_for(future, timeout=None)
  File "D:\Python310\lib\asyncio\tasks.py", line 408, in wait_for
    return await fut
  File "D:\Python310\lib\concurrent\futures\thread.py", line 52, in run
    result = self.fn(*self.args, **self.kwargs)
  File "D:\pythonList\web_python310\lib\site-packages\asgiref\sync.py", line 476, in thread_handler
    return func(*args, **kwargs)
  File "D:\pythonList\web_python310\lib\site-packages\django\views\decorators\csrf.py", line 54, in wrapped_view
    return view_func(*args, **kwargs)
  File "D:\pythonList\web_python310\lib\site-packages\django\views\generic\base.py", line 103, in view
    return self.dispatch(request, *args, **kwargs)
  File "D:\pythonList\web_python310\lib\site-packages\rest_framework\views.py", line 509, in dispatch
    response = self.handle_exception(exc)
  File "D:\pythonList\web_python310\lib\site-packages\rest_framework\views.py", line 469, in handle_exception
    self.raise_uncaught_exception(exc)
  File "D:\pythonList\web_python310\lib\site-packages\rest_framework\views.py", line 480, in raise_uncaught_exception
    raise exc
  File "D:\pythonList\web_python310\lib\site-packages\rest_framework\views.py", line 506, in dispatch
    response = handler(request, *args, **kwargs)
  File "C:\Users\Administrator\Desktop\myweb\myweb\saas\views.py", line 440, in post
    serialize.save()
  File "D:\pythonList\web_python310\lib\site-packages\rest_framework\serializers.py", line 212, in save
    self.instance = self.create(validated_data)
  File "D:\pythonList\web_python310\lib\site-packages\rest_framework\serializers.py", line 962, in create
    instance = ModelClass._default_manager.create(**validated_data)
  File "D:\pythonList\web_python310\lib\site-packages\django\db\models\manager.py", line 85, in manager_method
    return getattr(self.get_queryset(), name)(*args, **kwargs)
  File "D:\pythonList\web_python310\lib\site-packages\django\db\models\query.py", line 671, in create
    obj.save(force_insert=True, using=self.db)
  File "D:\pythonList\web_python310\lib\site-packages\django\db\models\base.py", line 812, in save
    self.save_base(
  File "D:\pythonList\web_python310\lib\site-packages\django\db\models\base.py", line 863, in save_base
    updated = self._save_table(
  File "D:\pythonList\web_python310\lib\site-packages\django\db\models\base.py", line 1006, in _save_table
    results = self._do_insert(
  File "D:\pythonList\web_python310\lib\site-packages\django\db\models\base.py", line 1047, in _do_insert
    return manager._insert(
  File "D:\pythonList\web_python310\lib\site-packages\django\db\models\manager.py", line 85, in manager_method
    return getattr(self.get_queryset(), name)(*args, **kwargs)
  File "D:\pythonList\web_python310\lib\site-packages\django\db\models\query.py", line 1791, in _insert
    return query.get_compiler(using=using).execute_sql(returning_fields)
  File "D:\pythonList\web_python310\lib\site-packages\django\db\models\sql\compiler.py", line 1660, in execute_sql
    cursor.execute(sql, params)
  File "D:\pythonList\web_python310\lib\site-packages\django\db\backends\utils.py", line 103, in execute
    return super().execute(sql, params)
  File "D:\pythonList\web_python310\lib\site-packages\django\db\backends\utils.py", line 67, in execute
    return self._execute_with_wrappers(
  File "D:\pythonList\web_python310\lib\site-packages\django\db\backends\utils.py", line 80, in _execute_with_wrappers
    return executor(sql, params, many, context)
  File "D:\pythonList\web_python310\lib\site-packages\django\db\backends\utils.py", line 84, in _execute
    with self.db.wrap_database_errors:
  File "D:\pythonList\web_python310\lib\site-packages\django\db\utils.py", line 91, in __exit__
    raise dj_exc_value.with_traceback(traceback) from exc_value
  File "D:\pythonList\web_python310\lib\site-packages\django\db\backends\utils.py", line 89, in _execute
    return self.cursor.execute(sql, params)
  File "D:\pythonList\web_python310\lib\site-packages\django\db\backends\mysql\base.py", line 75, in execute
    return self.cursor.execute(query, args)
  File "D:\pythonList\web_python310\lib\site-packages\pymysql\cursors.py", line 148, in execute
    result = self._query(query)
  File "D:\pythonList\web_python310\lib\site-packages\pymysql\cursors.py", line 310, in _query
    conn.query(q)
  File "D:\pythonList\web_python310\lib\site-packages\pymysql\connections.py", line 548, in query
    self._affected_rows = self._read_query_result(unbuffered=unbuffered)
  File "D:\pythonList\web_python310\lib\site-packages\pymysql\connections.py", line 775, in _read_query_result
    result.read()
  File "D:\pythonList\web_python310\lib\site-packages\pymysql\connections.py", line 1156, in read
    first_packet = self.connection._read_packet()
  File "D:\pythonList\web_python310\lib\site-packages\pymysql\connections.py", line 725, in _read_packet
    packet.raise_for_error()
  File "D:\pythonList\web_python310\lib\site-packages\pymysql\protocol.py", line 221, in raise_for_error
    err.raise_mysql_exception(self._data)
  File "D:\pythonList\web_python310\lib\site-packages\pymysql\err.py", line 143, in raise_mysql_exception
    raise errorclass(errno, errval)
django.db.utils.DataError: (1366, 'Incorrect string value: \'\\xF0\\x9F\\xA4\\x97",...\' for column \'unchange\' at row 1')
[2023-01-10 19:35:50,061] [runserver.py:160] [runserver:log_action] [ERROR]- HTTP POST /cases/ 500 [0.37, 127.0.0.1:64057]
[2023-01-10 19:36:42,149] [runserver.py:147] [runserver:log_action] [INFO]- HTTP POST /cases/ 200 [0.09, 127.0.0.1:64080]
[2023-01-10 19:36:48,066] [runserver.py:147] [runserver:log_action] [INFO]- HTTP GET /cases/ 200 [0.10, 127.0.0.1:64092]
[2023-01-10 19:36:54,330] [runserver.py:147] [runserver:log_action] [INFO]- HTTP GET /cases/?page=2 200 [0.08, 127.0.0.1:64098]
[2023-01-10 19:36:55,837] [runserver.py:147] [runserver:log_action] [INFO]- HTTP GET /cases/?page=1 200 [0.05, 127.0.0.1:64104]
[2023-01-10 19:37:02,492] [fiddlerExe.py:37] [fiddlerExe:getDatas] [INFO]- True
[2023-01-10 19:37:02,516] [runserver.py:147] [runserver:log_action] [INFO]- HTTP POST /dealFiddlerNotSql/ 200 [0.03, 127.0.0.1:64113]
[2023-01-10 20:03:41,203] [runserver.py:147] [runserver:log_action] [INFO]- HTTP GET /cases/ 200 [57.70, 127.0.0.1:49190]
[2023-01-10 20:03:41,549] [runserver.py:147] [runserver:log_action] [INFO]- HTTP GET /cases/ 200 [35.72, 127.0.0.1:49208]
[2023-01-10 20:03:41,558] [runserver.py:147] [runserver:log_action] [INFO]- HTTP GET /cases/ 200 [12.13, 127.0.0.1:49236]
[2023-01-10 20:03:41,560] [runserver.py:147] [runserver:log_action] [INFO]- HTTP GET /cases/ 200 [122.81, 127.0.0.1:65513]
[2023-01-10 20:04:47,474] [runserver.py:147] [runserver:log_action] [INFO]- HTTP GET /cases/?search=book 200 [3.96, 127.0.0.1:49298]
[2023-01-10 20:04:48,360] [runserver.py:147] [runserver:log_action] [INFO]- HTTP GET /cases/?search=book 200 [0.82, 127.0.0.1:49305]
[2023-01-10 20:05:01,924] [runserver.py:147] [runserver:log_action] [INFO]- HTTP GET /projects/ 200 [1.37, 127.0.0.1:49321]
[2023-01-10 20:05:02,124] [runserver.py:147] [runserver:log_action] [INFO]- HTTP GET /projects/ 200 [0.72, 127.0.0.1:49331]
[2023-01-10 20:05:03,382] [runserver.py:147] [runserver:log_action] [INFO]- HTTP GET /modules/ 200 [0.39, 127.0.0.1:49333]
[2023-01-10 20:05:04,017] [runserver.py:147] [runserver:log_action] [INFO]- HTTP GET /modules/ 200 [0.30, 127.0.0.1:49339]
[2023-01-10 20:05:07,130] [runserver.py:147] [runserver:log_action] [INFO]- HTTP GET /projects/ 200 [0.07, 127.0.0.1:49343]
[2023-01-10 20:05:12,879] [runserver.py:147] [runserver:log_action] [INFO]- HTTP GET /modules/ 200 [0.10, 127.0.0.1:49355]
[2023-01-10 20:05:13,559] [runserver.py:147] [runserver:log_action] [INFO]- HTTP GET /modules/ 200 [0.09, 127.0.0.1:49358]
[2023-01-10 20:05:17,626] [runserver.py:147] [runserver:log_action] [INFO]- HTTP GET /projects/ 200 [0.10, 127.0.0.1:49363]
[2023-01-10 20:05:18,347] [runserver.py:147] [runserver:log_action] [INFO]- HTTP GET /projects/ 200 [0.07, 127.0.0.1:49370]
[2023-01-10 20:05:22,665] [runserver.py:147] [runserver:log_action] [INFO]- HTTP GET /projects/36 200 [0.14, 127.0.0.1:49378]
[2023-01-10 20:05:25,373] [runserver.py:147] [runserver:log_action] [INFO]- HTTP GET /projects/ 200 [0.08, 127.0.0.1:49382]
[2023-01-10 20:05:28,871] [runserver.py:147] [runserver:log_action] [INFO]- HTTP GET /projects/37 200 [0.07, 127.0.0.1:49388]
[2023-01-10 20:05:33,913] [runserver.py:147] [runserver:log_action] [INFO]- HTTP GET /projects/ 200 [0.07, 127.0.0.1:49397]
[2023-01-10 20:05:34,310] [runserver.py:147] [runserver:log_action] [INFO]- HTTP GET /projects/ 200 [0.04, 127.0.0.1:49407]
[2023-01-10 20:05:35,298] [runserver.py:147] [runserver:log_action] [INFO]- HTTP GET /modules/ 200 [0.06, 127.0.0.1:49411]
[2023-01-10 20:05:35,834] [runserver.py:147] [runserver:log_action] [INFO]- HTTP GET /modules/ 200 [0.15, 127.0.0.1:49414]
[2023-01-10 20:05:37,852] [runserver.py:147] [runserver:log_action] [INFO]- HTTP GET /projects/ 200 [0.08, 127.0.0.1:49417]
[2023-01-10 20:05:38,601] [runserver.py:147] [runserver:log_action] [INFO]- HTTP GET /projects/ 200 [0.04, 127.0.0.1:49424]
[2023-01-10 20:05:43,588] [runserver.py:147] [runserver:log_action] [INFO]- HTTP GET /modules/ 200 [0.04, 127.0.0.1:49433]
[2023-01-10 20:05:43,998] [runserver.py:147] [runserver:log_action] [INFO]- HTTP GET /modules/ 200 [0.05, 127.0.0.1:49442]
[2023-01-10 20:05:47,571] [runserver.py:147] [runserver:log_action] [INFO]- HTTP GET /projects/ 200 [0.07, 127.0.0.1:49448]
[2023-01-10 20:05:47,728] [runserver.py:147] [runserver:log_action] [INFO]- HTTP GET /cases/ 200 [0.22, 127.0.0.1:49449]
[2023-01-10 20:05:48,372] [runserver.py:147] [runserver:log_action] [INFO]- HTTP GET /projects/ 200 [0.04, 127.0.0.1:49456]
[2023-01-10 20:05:48,491] [runserver.py:147] [runserver:log_action] [INFO]- HTTP GET /cases/ 200 [0.14, 127.0.0.1:49459]
[2023-01-10 20:05:50,261] [runserver.py:147] [runserver:log_action] [INFO]- HTTP GET /modules/?project=36 200 [0.08, 127.0.0.1:49466]
[2023-01-10 20:06:10,275] [runserver.py:147] [runserver:log_action] [INFO]- HTTP GET /cases/ 200 [0.14, 127.0.0.1:49480]
[2023-01-10 20:06:11,335] [runserver.py:147] [runserver:log_action] [INFO]- HTTP GET /cases/ 200 [0.07, 127.0.0.1:49495]
[2023-01-10 20:08:38,807] [runserver.py:147] [runserver:log_action] [INFO]- HTTP GET /cases/?page=2 200 [0.12, 127.0.0.1:49566]
[2023-01-10 20:08:51,300] [runserver.py:147] [runserver:log_action] [INFO]- HTTP GET /projects/ 200 [0.11, 127.0.0.1:49579]
[2023-01-10 20:08:51,334] [runserver.py:147] [runserver:log_action] [INFO]- HTTP GET /cases/ 200 [0.11, 127.0.0.1:49582]
[2023-01-10 20:08:51,518] [runserver.py:147] [runserver:log_action] [INFO]- HTTP GET /cases/143 200 [0.07, 127.0.0.1:49587]
[2023-01-10 20:08:51,733] [runserver.py:147] [runserver:log_action] [INFO]- HTTP GET /modules/?project= 200 [0.05, 127.0.0.1:49591]
[2023-01-10 20:09:20,998] [runserver.py:147] [runserver:log_action] [INFO]- HTTP GET /cases/ 200 [0.12, 127.0.0.1:49605]
[2023-01-10 20:09:23,453] [runserver.py:147] [runserver:log_action] [INFO]- HTTP GET /projects/ 200 [0.04, 127.0.0.1:49611]
[2023-01-10 20:09:23,839] [runserver.py:147] [runserver:log_action] [INFO]- HTTP GET /cases/ 200 [0.11, 127.0.0.1:49614]
[2023-01-10 20:09:24,287] [runserver.py:147] [runserver:log_action] [INFO]- HTTP GET /modules/?project= 200 [0.09, 127.0.0.1:49622]
[2023-01-10 20:09:24,422] [runserver.py:147] [runserver:log_action] [INFO]- HTTP GET /cases/135 200 [0.23, 127.0.0.1:49621]
[2023-01-10 20:09:40,302] [runserver.py:147] [runserver:log_action] [INFO]- HTTP GET /cases/ 200 [0.11, 127.0.0.1:49633]
[2023-01-10 20:12:07,147] [runserver.py:147] [runserver:log_action] [INFO]- HTTP GET /cases/?size=500 200 [0.26, 127.0.0.1:49704]
[2023-01-10 20:12:19,609] [runserver.py:147] [runserver:log_action] [INFO]- HTTP DELETE /cases/138 200 [1.17, 127.0.0.1:49730]
[2023-01-10 20:12:19,655] [runserver.py:147] [runserver:log_action] [INFO]- HTTP DELETE /cases/134 200 [1.23, 127.0.0.1:49726]
[2023-01-10 20:12:19,655] [runserver.py:147] [runserver:log_action] [INFO]- HTTP DELETE /cases/135 200 [1.22, 127.0.0.1:49728]
[2023-01-10 20:12:19,655] [runserver.py:147] [runserver:log_action] [INFO]- HTTP DELETE /cases/133 200 [1.23, 127.0.0.1:49725]
[2023-01-10 20:12:19,671] [runserver.py:147] [runserver:log_action] [INFO]- HTTP DELETE /cases/137 200 [1.23, 127.0.0.1:49729]
[2023-01-10 20:12:19,997] [runserver.py:147] [runserver:log_action] [INFO]- HTTP DELETE /cases/136 200 [1.57, 127.0.0.1:49727]
[2023-01-10 20:12:20,672] [runserver.py:147] [runserver:log_action] [INFO]- HTTP DELETE /cases/140 200 [0.46, 127.0.0.1:49755]
[2023-01-10 20:12:20,677] [runserver.py:147] [runserver:log_action] [INFO]- HTTP DELETE /cases/142 200 [0.46, 127.0.0.1:49757]
[2023-01-10 20:12:20,692] [runserver.py:147] [runserver:log_action] [INFO]- HTTP DELETE /cases/141 200 [0.48, 127.0.0.1:49756]
[2023-01-10 20:12:20,697] [runserver.py:147] [runserver:log_action] [INFO]- HTTP DELETE /cases/139 200 [0.49, 127.0.0.1:49754]
[2023-01-10 20:12:20,961] [runserver.py:147] [runserver:log_action] [INFO]- HTTP GET /cases/ 200 [0.11, 127.0.0.1:49769]
[2023-01-10 20:18:41,002] [runserver.py:147] [runserver:log_action] [INFO]- HTTP DELETE /cases/145 200 [0.34, 127.0.0.1:50096]
[2023-01-10 20:18:41,019] [runserver.py:147] [runserver:log_action] [INFO]- HTTP DELETE /cases/144 200 [0.36, 127.0.0.1:50095]
[2023-01-10 20:18:41,077] [runserver.py:147] [runserver:log_action] [INFO]- HTTP DELETE /cases/146 200 [0.41, 127.0.0.1:50097]
[2023-01-10 20:18:41,083] [runserver.py:147] [runserver:log_action] [INFO]- HTTP DELETE /cases/143 200 [0.41, 127.0.0.1:50098]
[2023-01-10 20:18:41,143] [runserver.py:147] [runserver:log_action] [INFO]- HTTP DELETE /cases/147 200 [0.47, 127.0.0.1:50099]
[2023-01-10 20:18:41,146] [runserver.py:147] [runserver:log_action] [INFO]- HTTP DELETE /cases/148 200 [0.47, 127.0.0.1:50100]
[2023-01-10 20:18:41,413] [runserver.py:147] [runserver:log_action] [INFO]- HTTP DELETE /cases/149 200 [0.09, 127.0.0.1:50114]
[2023-01-10 20:18:42,301] [runserver.py:147] [runserver:log_action] [INFO]- HTTP GET /cases/ 200 [0.08, 127.0.0.1:50126]
[2023-01-10 20:18:46,924] [runserver.py:147] [runserver:log_action] [INFO]- HTTP DELETE /cases/150 200 [0.05, 127.0.0.1:50134]
[2023-01-10 20:18:47,617] [runserver.py:147] [runserver:log_action] [INFO]- HTTP GET /cases/ 200 [0.06, 127.0.0.1:50141]
[2023-01-10 20:19:05,567] [fiddlerExe.py:37] [fiddlerExe:getDatas] [INFO]- True
[2023-01-10 20:19:05,781] [runserver.py:147] [runserver:log_action] [INFO]- HTTP POST /dealFiddler/ 200 [0.78, 127.0.0.1:50158]
[2023-01-10 20:19:09,303] [runserver.py:147] [runserver:log_action] [INFO]- HTTP POST /cases/ 200 [0.78, 127.0.0.1:50178]
[2023-01-10 20:19:09,324] [runserver.py:147] [runserver:log_action] [INFO]- HTTP POST /cases/ 200 [0.80, 127.0.0.1:50177]
[2023-01-10 20:19:09,330] [runserver.py:147] [runserver:log_action] [INFO]- HTTP POST /cases/ 200 [0.89, 127.0.0.1:50173]
[2023-01-10 20:19:09,350] [runserver.py:147] [runserver:log_action] [INFO]- HTTP POST /cases/ 200 [0.85, 127.0.0.1:50176]
[2023-01-10 20:19:09,395] [runserver.py:147] [runserver:log_action] [INFO]- HTTP POST /cases/ 200 [0.92, 127.0.0.1:50175]
[2023-01-10 20:19:09,418] [runserver.py:147] [runserver:log_action] [INFO]- HTTP POST /cases/ 200 [0.98, 127.0.0.1:50174]
[2023-01-10 20:19:10,203] [runserver.py:147] [runserver:log_action] [INFO]- HTTP POST /cases/ 200 [0.55, 127.0.0.1:50195]
[2023-01-10 20:19:10,606] [runserver.py:147] [runserver:log_action] [INFO]- HTTP POST /cases/ 200 [0.84, 127.0.0.1:50201]
[2023-01-10 20:19:10,611] [runserver.py:147] [runserver:log_action] [INFO]- HTTP POST /cases/ 200 [0.89, 127.0.0.1:50200]
[2023-01-10 20:19:10,615] [runserver.py:147] [runserver:log_action] [INFO]- HTTP POST /cases/ 200 [0.85, 127.0.0.1:50202]
[2023-01-10 20:19:10,618] [runserver.py:147] [runserver:log_action] [INFO]- HTTP POST /cases/ 200 [0.81, 127.0.0.1:50204]
[2023-01-10 20:19:21,222] [runserver.py:147] [runserver:log_action] [INFO]- HTTP POST /cases/ 200 [10.62, 127.0.0.1:50211]
[2023-01-10 20:19:21,526] [runserver.py:147] [runserver:log_action] [INFO]- HTTP POST /cases/ 200 [10.45, 127.0.0.1:50221]
[2023-01-10 20:19:21,723] [runserver.py:147] [runserver:log_action] [INFO]- HTTP POST /cases/ 200 [10.64, 127.0.0.1:50222]
[2023-01-10 20:19:21,724] [runserver.py:147] [runserver:log_action] [INFO]- HTTP POST /cases/ 200 [0.56, 127.0.0.1:50224]
[2023-01-10 20:19:21,736] [runserver.py:147] [runserver:log_action] [INFO]- HTTP POST /cases/ 200 [0.57, 127.0.0.1:50223]
[2023-01-10 20:19:21,857] [runserver.py:147] [runserver:log_action] [INFO]- HTTP POST /cases/ 200 [0.21, 127.0.0.1:50237]
[2023-01-10 20:19:22,977] [log.py:241] [log:log_response] [ERROR]- Internal Server Error: /cases/
Traceback (most recent call last):
  File "D:\pythonList\web_python310\lib\site-packages\django\db\backends\utils.py", line 89, in _execute
    return self.cursor.execute(sql, params)
  File "D:\pythonList\web_python310\lib\site-packages\django\db\backends\mysql\base.py", line 75, in execute
    return self.cursor.execute(query, args)
  File "D:\pythonList\web_python310\lib\site-packages\pymysql\cursors.py", line 148, in execute
    result = self._query(query)
  File "D:\pythonList\web_python310\lib\site-packages\pymysql\cursors.py", line 310, in _query
    conn.query(q)
  File "D:\pythonList\web_python310\lib\site-packages\pymysql\connections.py", line 548, in query
    self._affected_rows = self._read_query_result(unbuffered=unbuffered)
  File "D:\pythonList\web_python310\lib\site-packages\pymysql\connections.py", line 775, in _read_query_result
    result.read()
  File "D:\pythonList\web_python310\lib\site-packages\pymysql\connections.py", line 1156, in read
    first_packet = self.connection._read_packet()
  File "D:\pythonList\web_python310\lib\site-packages\pymysql\connections.py", line 725, in _read_packet
    packet.raise_for_error()
  File "D:\pythonList\web_python310\lib\site-packages\pymysql\protocol.py", line 221, in raise_for_error
    err.raise_mysql_exception(self._data)
  File "D:\pythonList\web_python310\lib\site-packages\pymysql\err.py", line 143, in raise_mysql_exception
    raise errorclass(errno, errval)
pymysql.err.DataError: (1366, 'Incorrect string value: \'\\xF0\\x9F\\xA4\\x97",...\' for column \'unchange\' at row 1')

The above exception was the direct cause of the following exception:

Traceback (most recent call last):
  File "D:\pythonList\web_python310\lib\site-packages\asgiref\sync.py", line 472, in thread_handler
    raise exc_info[1]
  File "D:\pythonList\web_python310\lib\site-packages\django\core\handlers\exception.py", line 42, in inner
    response = await get_response(request)
  File "D:\pythonList\web_python310\lib\site-packages\django\core\handlers\base.py", line 253, in _get_response_async
    response = await wrapped_callback(
  File "D:\pythonList\web_python310\lib\site-packages\asgiref\sync.py", line 435, in __call__
    ret = await asyncio.wait_for(future, timeout=None)
  File "D:\Python310\lib\asyncio\tasks.py", line 408, in wait_for
    return await fut
  File "D:\Python310\lib\concurrent\futures\thread.py", line 52, in run
    result = self.fn(*self.args, **self.kwargs)
  File "D:\pythonList\web_python310\lib\site-packages\asgiref\sync.py", line 476, in thread_handler
    return func(*args, **kwargs)
  File "D:\pythonList\web_python310\lib\site-packages\django\views\decorators\csrf.py", line 54, in wrapped_view
    return view_func(*args, **kwargs)
  File "D:\pythonList\web_python310\lib\site-packages\django\views\generic\base.py", line 103, in view
    return self.dispatch(request, *args, **kwargs)
  File "D:\pythonList\web_python310\lib\site-packages\rest_framework\views.py", line 509, in dispatch
    response = self.handle_exception(exc)
  File "D:\pythonList\web_python310\lib\site-packages\rest_framework\views.py", line 469, in handle_exception
    self.raise_uncaught_exception(exc)
  File "D:\pythonList\web_python310\lib\site-packages\rest_framework\views.py", line 480, in raise_uncaught_exception
    raise exc
  File "D:\pythonList\web_python310\lib\site-packages\rest_framework\views.py", line 506, in dispatch
    response = handler(request, *args, **kwargs)
  File "C:\Users\Administrator\Desktop\myweb\myweb\saas\views.py", line 440, in post
    serialize.save()
  File "D:\pythonList\web_python310\lib\site-packages\rest_framework\serializers.py", line 212, in save
    self.instance = self.create(validated_data)
  File "D:\pythonList\web_python310\lib\site-packages\rest_framework\serializers.py", line 962, in create
    instance = ModelClass._default_manager.create(**validated_data)
  File "D:\pythonList\web_python310\lib\site-packages\django\db\models\manager.py", line 85, in manager_method
    return getattr(self.get_queryset(), name)(*args, **kwargs)
  File "D:\pythonList\web_python310\lib\site-packages\django\db\models\query.py", line 671, in create
    obj.save(force_insert=True, using=self.db)
  File "D:\pythonList\web_python310\lib\site-packages\django\db\models\base.py", line 812, in save
    self.save_base(
  File "D:\pythonList\web_python310\lib\site-packages\django\db\models\base.py", line 863, in save_base
    updated = self._save_table(
  File "D:\pythonList\web_python310\lib\site-packages\django\db\models\base.py", line 1006, in _save_table
    results = self._do_insert(
  File "D:\pythonList\web_python310\lib\site-packages\django\db\models\base.py", line 1047, in _do_insert
    return manager._insert(
  File "D:\pythonList\web_python310\lib\site-packages\django\db\models\manager.py", line 85, in manager_method
    return getattr(self.get_queryset(), name)(*args, **kwargs)
  File "D:\pythonList\web_python310\lib\site-packages\django\db\models\query.py", line 1791, in _insert
    return query.get_compiler(using=using).execute_sql(returning_fields)
  File "D:\pythonList\web_python310\lib\site-packages\django\db\models\sql\compiler.py", line 1660, in execute_sql
    cursor.execute(sql, params)
  File "D:\pythonList\web_python310\lib\site-packages\django\db\backends\utils.py", line 103, in execute
    return super().execute(sql, params)
  File "D:\pythonList\web_python310\lib\site-packages\django\db\backends\utils.py", line 67, in execute
    return self._execute_with_wrappers(
  File "D:\pythonList\web_python310\lib\site-packages\django\db\backends\utils.py", line 80, in _execute_with_wrappers
    return executor(sql, params, many, context)
  File "D:\pythonList\web_python310\lib\site-packages\django\db\backends\utils.py", line 84, in _execute
    with self.db.wrap_database_errors:
  File "D:\pythonList\web_python310\lib\site-packages\django\db\utils.py", line 91, in __exit__
    raise dj_exc_value.with_traceback(traceback) from exc_value
  File "D:\pythonList\web_python310\lib\site-packages\django\db\backends\utils.py", line 89, in _execute
    return self.cursor.execute(sql, params)
  File "D:\pythonList\web_python310\lib\site-packages\django\db\backends\mysql\base.py", line 75, in execute
    return self.cursor.execute(query, args)
  File "D:\pythonList\web_python310\lib\site-packages\pymysql\cursors.py", line 148, in execute
    result = self._query(query)
  File "D:\pythonList\web_python310\lib\site-packages\pymysql\cursors.py", line 310, in _query
    conn.query(q)
  File "D:\pythonList\web_python310\lib\site-packages\pymysql\connections.py", line 548, in query
    self._affected_rows = self._read_query_result(unbuffered=unbuffered)
  File "D:\pythonList\web_python310\lib\site-packages\pymysql\connections.py", line 775, in _read_query_result
    result.read()
  File "D:\pythonList\web_python310\lib\site-packages\pymysql\connections.py", line 1156, in read
    first_packet = self.connection._read_packet()
  File "D:\pythonList\web_python310\lib\site-packages\pymysql\connections.py", line 725, in _read_packet
    packet.raise_for_error()
  File "D:\pythonList\web_python310\lib\site-packages\pymysql\protocol.py", line 221, in raise_for_error
    err.raise_mysql_exception(self._data)
  File "D:\pythonList\web_python310\lib\site-packages\pymysql\err.py", line 143, in raise_mysql_exception
    raise errorclass(errno, errval)
django.db.utils.DataError: (1366, 'Incorrect string value: \'\\xF0\\x9F\\xA4\\x97",...\' for column \'unchange\' at row 1')
[2023-01-10 20:19:23,081] [runserver.py:160] [runserver:log_action] [ERROR]- HTTP POST /cases/ 500 [13.45, 127.0.0.1:50192]
[2023-01-10 20:19:23,104] [runserver.py:147] [runserver:log_action] [INFO]- HTTP GET /cases/ 200 [0.39, 127.0.0.1:50248]
[2023-01-10 20:19:28,485] [runserver.py:147] [runserver:log_action] [INFO]- HTTP GET /cases/?size=500 200 [0.15, 127.0.0.1:50259]
[2023-01-10 20:20:43,172] [runserver.py:147] [runserver:log_action] [INFO]- HTTP GET /cases/ 200 [0.18, 127.0.0.1:50299]
[2023-01-10 20:20:56,742] [runserver.py:147] [runserver:log_action] [INFO]- HTTP GET /cases/ 200 [0.16, 127.0.0.1:50327]
[2023-01-10 20:21:25,522] [runserver.py:147] [runserver:log_action] [INFO]- HTTP GET /cases/?size=500 200 [0.15, 127.0.0.1:50366]
[2023-01-10 20:22:44,499] [runserver.py:147] [runserver:log_action] [INFO]- HTTP GET /cases/ 200 [0.16, 127.0.0.1:50469]
[2023-01-10 20:22:53,183] [runserver.py:147] [runserver:log_action] [INFO]- HTTP GET /cases/?size=500 200 [0.16, 127.0.0.1:50486]
[2023-01-10 20:22:58,821] [runserver.py:147] [runserver:log_action] [INFO]- HTTP DELETE /cases/151 200 [0.17, 127.0.0.1:50498]
[2023-01-10 20:22:59,622] [runserver.py:147] [runserver:log_action] [INFO]- HTTP GET /cases/ 200 [0.16, 127.0.0.1:50508]
[2023-01-10 20:23:07,838] [runserver.py:147] [runserver:log_action] [INFO]- HTTP GET /cases/?page=2 200 [0.15, 127.0.0.1:50513]
[2023-01-10 20:23:09,093] [runserver.py:147] [runserver:log_action] [INFO]- HTTP GET /cases/?page=1 200 [0.11, 127.0.0.1:50519]
[2023-01-10 20:23:47,607] [runserver.py:147] [runserver:log_action] [INFO]- HTTP GET /cases/?size=500 200 [0.19, 127.0.0.1:50543]
[2023-01-10 20:31:57,568] [runserver.py:147] [runserver:log_action] [INFO]- HTTP GET /cases/ 200 [0.29, 127.0.0.1:51255]
[2023-01-10 20:32:01,386] [runserver.py:147] [runserver:log_action] [INFO]- HTTP GET /cases/?size=500 200 [0.14, 127.0.0.1:51268]
[2023-01-10 20:32:07,750] [runserver.py:147] [runserver:log_action] [INFO]- HTTP DELETE /cases/152 200 [0.37, 127.0.0.1:51286]
[2023-01-10 20:32:07,757] [runserver.py:147] [runserver:log_action] [INFO]- HTTP DELETE /cases/153 200 [0.38, 127.0.0.1:51287]
[2023-01-10 20:32:07,759] [runserver.py:147] [runserver:log_action] [INFO]- HTTP DELETE /cases/155 200 [0.37, 127.0.0.1:51289]
[2023-01-10 20:32:07,794] [runserver.py:147] [runserver:log_action] [INFO]- HTTP DELETE /cases/154 200 [0.41, 127.0.0.1:51288]
[2023-01-10 20:32:07,807] [runserver.py:147] [runserver:log_action] [INFO]- HTTP DELETE /cases/157 200 [0.42, 127.0.0.1:51291]
[2023-01-10 20:32:07,810] [runserver.py:147] [runserver:log_action] [INFO]- HTTP DELETE /cases/156 200 [0.42, 127.0.0.1:51290]
[2023-01-10 20:32:08,397] [runserver.py:147] [runserver:log_action] [INFO]- HTTP DELETE /cases/160 200 [0.32, 127.0.0.1:51309]
[2023-01-10 20:32:08,399] [runserver.py:147] [runserver:log_action] [INFO]- HTTP DELETE /cases/159 200 [0.32, 127.0.0.1:51308]
[2023-01-10 20:32:08,408] [runserver.py:147] [runserver:log_action] [INFO]- HTTP DELETE /cases/158 200 [0.33, 127.0.0.1:51307]
[2023-01-10 20:32:08,414] [runserver.py:147] [runserver:log_action] [INFO]- HTTP DELETE /cases/161 200 [0.31, 127.0.0.1:51314]
[2023-01-10 20:32:08,426] [runserver.py:147] [runserver:log_action] [INFO]- HTTP DELETE /cases/162 200 [0.30, 127.0.0.1:51318]
[2023-01-10 20:32:08,441] [runserver.py:147] [runserver:log_action] [INFO]- HTTP DELETE /cases/163 200 [0.32, 127.0.0.1:51319]
[2023-01-10 20:32:08,975] [runserver.py:147] [runserver:log_action] [INFO]- HTTP DELETE /cases/165 200 [0.25, 127.0.0.1:51330]
[2023-01-10 20:32:08,980] [runserver.py:147] [runserver:log_action] [INFO]- HTTP DELETE /cases/167 200 [0.24, 127.0.0.1:51333]
[2023-01-10 20:32:08,983] [runserver.py:147] [runserver:log_action] [INFO]- HTTP DELETE /cases/164 200 [0.27, 127.0.0.1:51327]
[2023-01-10 20:32:08,985] [runserver.py:147] [runserver:log_action] [INFO]- HTTP DELETE /cases/166 200 [0.25, 127.0.0.1:51332]
[2023-01-10 20:32:20,450] [runserver.py:147] [runserver:log_action] [INFO]- HTTP GET /cases/ 200 [0.11, 127.0.0.1:51351]
